Workbook

Sheet Sheet1
A1: ID | B1: 容器等级 | C1: 容器名称 | D1: 掉落品质 | E1: 掉落物 | F1: 权重万分比 | G1: 长 | H1: 宽 | I1: 面积 | J1: 价值 | K1: 权重改1 | L1: 权重改2 | M1: 概率 | N1: 期望价值 | S1: 白 | T1: 绿 | U1: 蓝 | V1: 紫 | W1: 金 | X1: 红
A2: -1
A3: 1 | B3: 1级容器 | C3: 陶罐1 | D3: 白 | E3: 生肉 | F3: =K3 -> 101 | G3: =VLOOKUP(E3,Sheet2!$B:$G,5,FALSE) -> 1 | H3: =VLOOKUP(E3,Sheet2!$B:$G,6,FALSE) -> 1 | I3: =G3*H3 -> 1 | J3: =VLOOKUP(E3,Sheet2!$B:$I,8,FALSE) -> 995 | K3: {=_xlfn.IFS(D3="白",ROUND(100000/J3,0),D3="绿",ROUND(300000/J3,0),D3="蓝",ROUND(1000000/J3,0),D3="紫",ROUND(3000000/J3,0),D3="金",ROUND(10000000/J3,0),D3="红",ROUND(30000000/J3,0))} -> 101 | L3: =IF(VLOOKUP(E3,Sheet2!$B:$V,21,FALSE)=1,K3,ROUND(K3/2,0)) -> 51 | M3: {=K3/VLOOKUP(C3,$R$1:$X$34,_xlfn.IFS(D3=S$1,2,D3=T$1,3,D3=U$1,4,D3=V$1,5,D3=W$1,6,D3=X$1,7),FALSE)} -> 0.027535442 | N3: =J3*M3 -> 27.397764 | R3: 保险柜 | S3: =SUMIFS($K:$K,$C:$C,$R3,$D:$D,S$1) -> 2202 | T3: =SUMIFS($K:$K,$C:$C,$R3,$D:$D,T$1) -> 386 | U3: =SUMIFS($K:$K,$C:$C,$R3,$D:$D,U$1) -> 601 | V3: =SUMIFS($K:$K,$C:$C,$R3,$D:$D,V$1) -> 1198 | W3: =SUMIFS($K:$K,$C:$C,$R3,$D:$D,W$1) -> 2385 | X3: =SUMIFS($K:$K,$C:$C,$R3,$D:$D,X$1) -> 2061
A4: 2 | B4: 1级容器 | C4: 陶罐1 | D4: 白 | E4: 粗制兽皮 | F4: =K4 -> 99 | G4: =VLOOKUP(E4,Sheet2!$B:$G,5,FALSE) -> 1 | H4: =VLOOKUP(E4,Sheet2!$B:$G,6,FALSE) -> 1 | I4: =G4*H4 -> 1 | J4: =VLOOKUP(E4,Sheet2!$B:$I,8,FALSE) -> 1006 | K4: {=_xlfn.IFS(D4="白",ROUND(100000/J4,0),D4="绿",ROUND(300000/J4,0),D4="蓝",ROUND(1000000/J4,0),D4="紫",ROUND(3000000/J4,0),D4="金",ROUND(10000000/J4,0),D4="红",ROUND(30000000/J4,0))} -> 99 | L4: =IF(VLOOKUP(E4,Sheet2!$B:$V,21,FALSE)=1,K4,ROUND(K4/2,0)) -> 50 | M4: {=K4/VLOOKUP(C4,$R$1:$X$34,_xlfn.IFS(D4=S$1,2,D4=T$1,3,D4=U$1,4,D4=V$1,5,D4=W$1,6,D4=X$1,7),FALSE)} -> 0.026990185 | N4: =J4*M4 -> 27.152126 | R4: 小保险箱 | S4: =SUMIFS($K:$K,$C:$C,$R4,$D:$D,S$1) -> 2303 | T4: =SUMIFS($K:$K,$C:$C,$R4,$D:$D,T$1) -> 1038 | U4: =SUMIFS($K:$K,$C:$C,$R4,$D:$D,U$1) -> 957 | V4: =SUMIFS($K:$K,$C:$C,$R4,$D:$D,V$1) -> 1813 | W4: =SUMIFS($K:$K,$C:$C,$R4,$D:$D,W$1) -> 3044 | X4: =SUMIFS($K:$K,$C:$C,$R4,$D:$D,X$1) -> 2582
A5: 3 | B5: 1级容器 | C5: 陶罐1 | D5: 白 | E5: 巨龟甲片 | F5: =K5 -> 28 | G5: =VLOOKUP(E5,Sheet2!$B:$G,5,FALSE) -> 2 | H5: =VLOOKUP(E5,Sheet2!$B:$G,6,FALSE) -> 2 | I5: =G5*H5 -> 4 | J5: =VLOOKUP(E5,Sheet2!$B:$I,8,FALSE) -> 3625 | K5: {=_xlfn.IFS(D5="白",ROUND(100000/J5,0),D5="绿",ROUND(300000/J5,0),D5="蓝",ROUND(1000000/J5,0),D5="紫",ROUND(3000000/J5,0),D5="金",ROUND(10000000/J5,0),D5="红",ROUND(30000000/J5,0))} -> 28 | L5: =IF(VLOOKUP(E5,Sheet2!$B:$V,21,FALSE)=1,K5,ROUND(K5/2,0)) -> 14 | M5: {=K5/VLOOKUP(C5,$R$1:$X$34,_xlfn.IFS(D5=S$1,2,D5=T$1,3,D5=U$1,4,D5=V$1,5,D5=W$1,6,D5=X$1,7),FALSE)} -> 0.0076335878 | N5: =J5*M5 -> 27.671756 | R5: 魔法仪器 | S5: =SUMIFS($K:$K,$C:$C,$R5,$D:$D,S$1) -> 304 | T5: =SUMIFS($K:$K,$C:$C,$R5,$D:$D,T$1) -> 202 | U5: =SUMIFS($K:$K,$C:$C,$R5,$D:$D,U$1) -> 203 | V5: =SUMIFS($K:$K,$C:$C,$R5,$D:$D,V$1) -> 653 | W5: =SUMIFS($K:$K,$C:$C,$R5,$D:$D,W$1) -> 911 | X5: =SUMIFS($K:$K,$C:$C,$R5,$D:$D,X$1) -> 812
A6: 4 | B6: 1级容器 | C6: 陶罐1 | D6: 白 | E6: 刻刀 | F6: =K6 -> 99 | G6: =VLOOKUP(E6,Sheet2!$B:$G,5,FALSE) -> 1 | H6: =VLOOKUP(E6,Sheet2!$B:$G,6,FALSE) -> 1 | I6: =G6*H6 -> 1 | J6: =VLOOKUP(E6,Sheet2!$B:$I,8,FALSE) -> 1009 | K6: {=_xlfn.IFS(D6="白",ROUND(100000/J6,0),D6="绿",ROUND(300000/J6,0),D6="蓝",ROUND(1000000/J6,0),D6="紫",ROUND(3000000/J6,0),D6="金",ROUND(10000000/J6,0),D6="红",ROUND(30000000/J6,0))} -> 99 | L6: =IF(VLOOKUP(E6,Sheet2!$B:$V,21,FALSE)=1,K6,ROUND(K6/2,0)) -> 50 | M6: {=K6/VLOOKUP(C6,$R$1:$X$34,_xlfn.IFS(D6=S$1,2,D6=T$1,3,D6=U$1,4,D6=V$1,5,D6=W$1,6,D6=X$1,7),FALSE)} -> 0.026990185 | N6: =J6*M6 -> 27.233097 | R6: 高级储物箱 | S6: =SUMIFS($K:$K,$C:$C,$R6,$D:$D,S$1) -> 4493 | T6: =SUMIFS($K:$K,$C:$C,$R6,$D:$D,T$1) -> 5225 | U6: =SUMIFS($K:$K,$C:$C,$R6,$D:$D,U$1) -> 5056 | V6: =SUMIFS($K:$K,$C:$C,$R6,$D:$D,V$1) -> 5481 | W6: =SUMIFS($K:$K,$C:$C,$R6,$D:$D,W$1) -> 6270 | X6: =SUMIFS($K:$K,$C:$C,$R6,$D:$D,X$1) -> 4549
A7: 5 | B7: 1级容器 | C7: 陶罐1 | D7: 白 | E7: 磨刀石 | F7: =K7 -> 52 | G7: =VLOOKUP(E7,Sheet2!$B:$G,5,FALSE) -> 1 | H7: =VLOOKUP(E7,Sheet2!$B:$G,6,FALSE) -> 2 | I7: =G7*H7 -> 2 | J7: =VLOOKUP(E7,Sheet2!$B:$I,8,FALSE) -> 1926 | K7: {=_xlfn.IFS(D7="白",ROUND(100000/J7,0),D7="绿",ROUND(300000/J7,0),D7="蓝",ROUND(1000000/J7,0),D7="紫",ROUND(3000000/J7,0),D7="金",ROUND(10000000/J7,0),D7="红",ROUND(30000000/J7,0))} -> 52 | L7: =IF(VLOOKUP(E7,Sheet2!$B:$V,21,FALSE)=1,K7,ROUND(K7/2,0)) -> 26 | M7: {=K7/VLOOKUP(C7,$R$1:$X$34,_xlfn.IFS(D7=S$1,2,D7=T$1,3,D7=U$1,4,D7=V$1,5,D7=W$1,6,D7=X$1,7),FALSE)} -> 0.014176663 | N7: =J7*M7 -> 27.304253 | R7: 高级旅行包 | S7: =SUMIFS($K:$K,$C:$C,$R7,$D:$D,S$1) -> 2989 | T7: =SUMIFS($K:$K,$C:$C,$R7,$D:$D,T$1) -> 1501 | U7: =SUMIFS($K:$K,$C:$C,$R7,$D:$D,U$1) -> 1583 | V7: =SUMIFS($K:$K,$C:$C,$R7,$D:$D,V$1) -> 2585 | W7: =SUMIFS($K:$K,$C:$C,$R7,$D:$D,W$1) -> 3948 | X7: =SUMIFS($K:$K,$C:$C,$R7,$D:$D,X$1) -> 3120
A8: 6 | B8: 1级容器 | C8: 陶罐1 | D8: 白 | E8: 线 | F8: =K8 -> 101 | G8: =VLOOKUP(E8,Sheet2!$B:$G,5,FALSE) -> 1 | H8: =VLOOKUP(E8,Sheet2!$B:$G,6,FALSE) -> 1 | I8: =G8*H8 -> 1 | J8: =VLOOKUP(E8,Sheet2!$B:$I,8,FALSE) -> 995 | K8: {=_xlfn.IFS(D8="白",ROUND(100000/J8,0),D8="绿",ROUND(300000/J8,0),D8="蓝",ROUND(1000000/J8,0),D8="紫",ROUND(3000000/J8,0),D8="金",ROUND(10000000/J8,0),D8="红",ROUND(30000000/J8,0))} -> 101 | L8: =IF(VLOOKUP(E8,Sheet2!$B:$V,21,FALSE)=1,K8,ROUND(K8/2,0)) -> 51 | M8: {=K8/VLOOKUP(C8,$R$1:$X$34,_xlfn.IFS(D8=S$1,2,D8=T$1,3,D8=U$1,4,D8=V$1,5,D8=W$1,6,D8=X$1,7),FALSE)} -> 0.027535442 | N8: =J8*M8 -> 27.397764 | R8: 魔法材料柜 | S8: =SUMIFS($K:$K,$C:$C,$R8,$D:$D,S$1) -> 101 | T8: =SUMIFS($K:$K,$C:$C,$R8,$D:$D,T$1) -> 1152 | U8: =SUMIFS($K:$K,$C:$C,$R8,$D:$D,U$1) -> 1028 | V8: =SUMIFS($K:$K,$C:$C,$R8,$D:$D,V$1) -> 852 | W8: =SUMIFS($K:$K,$C:$C,$R8,$D:$D,W$1) -> 748 | X8: =SUMIFS($K:$K,$C:$C,$R8,$D:$D,X$1) -> 684
A9: 7 | B9: 1级容器 | C9: 陶罐1 | D9: 白 | E9: 空瓶 | F9: =K9 -> 51 | G9: =VLOOKUP(E9,Sheet2!$B:$G,5,FALSE) -> 1 | H9: =VLOOKUP(E9,Sheet2!$B:$G,6,FALSE) -> 2 | I9: =G9*H9 -> 2 | J9: =VLOOKUP(E9,Sheet2!$B:$I,8,FALSE) -> 1942 | K9: {=_xlfn.IFS(D9="白",ROUND(100000/J9,0),D9="绿",ROUND(300000/J9,0),D9="蓝",ROUND(1000000/J9,0),D9="紫",ROUND(3000000/J9,0),D9="金",ROUND(10000000/J9,0),D9="红",ROUND(30000000/J9,0))} -> 51 | L9: =IF(VLOOKUP(E9,Sheet2!$B:$V,21,FALSE)=1,K9,ROUND(K9/2,0)) -> 26 | M9: {=K9/VLOOKUP(C9,$R$1:$X$34,_xlfn.IFS(D9=S$1,2,D9=T$1,3,D9=U$1,4,D9=V$1,5,D9=W$1,6,D9=X$1,7),FALSE)} -> 0.013904035 | N9: =J9*M9 -> 27.001636 | R9: 魔晶核箱 | S9: =SUMIFS($K:$K,$C:$C,$R9,$D:$D,S$1) -> 100 | T9: =SUMIFS($K:$K,$C:$C,$R9,$D:$D,T$1) -> 1899 | U9: =SUMIFS($K:$K,$C:$C,$R9,$D:$D,U$1) -> 3794 | V9: =SUMIFS($K:$K,$C:$C,$R9,$D:$D,V$1) -> 6603 | W9: =SUMIFS($K:$K,$C:$C,$R9,$D:$D,W$1) -> 6612 | X9: =SUMIFS($K:$K,$C:$C,$R9,$D:$D,X$1) -> 6598
A10: 8 | B10: 1级容器 | C10: 陶罐1 | D10: 白 | E10: 炼金瓶 | F10: =K10 -> 27 | G10: =VLOOKUP(E10,Sheet2!$B:$G,5,FALSE) -> 2 | H10: =VLOOKUP(E10,Sheet2!$B:$G,6,FALSE) -> 2 | I10: =G10*H10 -> 4 | J10: =VLOOKUP(E10,Sheet2!$B:$I,8,FALSE) -> 3673 | K10: {=_xlfn.IFS(D10="白",ROUND(100000/J10,0),D10="绿",ROUND(300000/J10,0),D10="蓝",ROUND(1000000/J10,0),D10="紫",ROUND(3000000/J10,0),D10="金",ROUND(10000000/J10,0),D10="红",ROUND(30000000/J10,0))} -> 27 | L10: =IF(VLOOKUP(E10,Sheet2!$B:$V,21,FALSE)=1,K10,ROUND(K10/2,0)) -> 14 | M10: {=K10/VLOOKUP(C10,$R$1:$X$34,_xlfn.IFS(D10=S$1,2,D10=T$1,3,D10=U$1,4,D10=V$1,5,D10=W$1,6,D10=X$1,7),FALSE)} -> 0.0073609597 | N10: =J10*M10 -> 27.036805 | R10: 医疗箱 | S10: =SUMIFS($K:$K,$C:$C,$R10,$D:$D,S$1) -> 927 | T10: =SUMIFS($K:$K,$C:$C,$R10,$D:$D,T$1) -> 1353 | U10: =SUMIFS($K:$K,$C:$C,$R10,$D:$D,U$1) -> 1074 | V10: =SUMIFS($K:$K,$C:$C,$R10,$D:$D,V$1) -> 808 | W10: =SUMIFS($K:$K,$C:$C,$R10,$D:$D,W$1) -> 785 | X10: =SUMIFS($K:$K,$C:$C,$R10,$D:$D,X$1) -> 121
A11: 9 | B11: 1级容器 | C11: 陶罐1 | D11: 白 | E11: 绳子 | F11: =K11 -> 52 | G11: =VLOOKUP(E11,Sheet2!$B:$G,5,FALSE) -> 1 | H11: =VLOOKUP(E11,Sheet2!$B:$G,6,FALSE) -> 2 | I11: =G11*H11 -> 2 | J11: =VLOOKUP(E11,Sheet2!$B:$I,8,FALSE) -> 1938 | K11: {=_xlfn.IFS(D11="白",ROUND(100000/J11,0),D11="绿",ROUND(300000/J11,0),D11="蓝",ROUND(1000000/J11,0),D11="紫",ROUND(3000000/J11,0),D11="金",ROUND(10000000/J11,0),D11="红",ROUND(30000000/J11,0))} -> 52 | L11: =IF(VLOOKUP(E11,Sheet2!$B:$V,21,FALSE)=1,K11,ROUND(K11/2,0)) -> 26 | M11: {=K11/VLOOKUP(C11,$R$1:$X$34,_xlfn.IFS(D11=S$1,2,D11=T$1,3,D11=U$1,4,D11=V$1,5,D11=W$1,6,D11=X$1,7),FALSE)} -> 0.014176663 | N11: =J11*M11 -> 27.474373 | R11: 手提箱 | S11: =SUMIFS($K:$K,$C:$C,$R11,$D:$D,S$1) -> 2989 | T11: =SUMIFS($K:$K,$C:$C,$R11,$D:$D,T$1) -> 1501 | U11: =SUMIFS($K:$K,$C:$C,$R11,$D:$D,U$1) -> 1583 | V11: =SUMIFS($K:$K,$C:$C,$R11,$D:$D,V$1) -> 2585 | W11: =SUMIFS($K:$K,$C:$C,$R11,$D:$D,W$1) -> 3948 | X11: =SUMIFS($K:$K,$C:$C,$R11,$D:$D,X$1) -> 3120
A12: 10 | B12: 1级容器 | C12: 陶罐1 | D12: 白 | E12: 木材 | F12: =K12 -> 51 | G12: =VLOOKUP(E12,Sheet2!$B:$G,5,FALSE) -> 1 | H12: =VLOOKUP(E12,Sheet2!$B:$G,6,FALSE) -> 2 | I12: =G12*H12 -> 2 | J12: =VLOOKUP(E12,Sheet2!$B:$I,8,FALSE) -> 1946 | K12: {=_xlfn.IFS(D12="白",ROUND(100000/J12,0),D12="绿",ROUND(300000/J12,0),D12="蓝",ROUND(1000000/J12,0),D12="紫",ROUND(3000000/J12,0),D12="金",ROUND(10000000/J12,0),D12="红",ROUND(30000000/J12,0))} -> 51 | L12: =IF(VLOOKUP(E12,Sheet2!$B:$V,21,FALSE)=1,K12,ROUND(K12/2,0)) -> 26 | M12: {=K12/VLOOKUP(C12,$R$1:$X$34,_xlfn.IFS(D12=S$1,2,D12=T$1,3,D12=U$1,4,D12=V$1,5,D12=W$1,6,D12=X$1,7),FALSE)} -> 0.013904035 | N12: =J12*M12 -> 27.057252 | R12: 武器箱 | S12: =SUMIFS($K:$K,$C:$C,$R12,$D:$D,S$1) -> 100 | T12: =SUMIFS($K:$K,$C:$C,$R12,$D:$D,T$1) -> 1899 | U12: =SUMIFS($K:$K,$C:$C,$R12,$D:$D,U$1) -> 3794 | V12: =SUMIFS($K:$K,$C:$C,$R12,$D:$D,V$1) -> 6603 | W12: =SUMIFS($K:$K,$C:$C,$R12,$D:$D,W$1) -> 6612 | X12: =SUMIFS($K:$K,$C:$C,$R12,$D:$D,X$1) -> 6598
A13: 11 | B13: 1级容器 | C13: 陶罐1 | D13: 白 | E13: 铁锁扣 | F13: =K13 -> 101 | G13: =VLOOKUP(E13,Sheet2!$B:$G,5,FALSE) -> 1 | H13: =VLOOKUP(E13,Sheet2!$B:$G,6,FALSE) -> 1 | I13: =G13*H13 -> 1 | J13: =VLOOKUP(E13,Sheet2!$B:$I,8,FALSE) -> 992 | K13: {=_xlfn.IFS(D13="白",ROUND(100000/J13,0),D13="绿",ROUND(300000/J13,0),D13="蓝",ROUND(1000000/J13,0),D13="紫",ROUND(3000000/J13,0),D13="金",ROUND(10000000/J13,0),D13="红",ROUND(30000000/J13,0))} -> 101 | L13: =IF(VLOOKUP(E13,Sheet2!$B:$V,21,FALSE)=1,K13,ROUND(K13/2,0)) -> 51 | M13: {=K13/VLOOKUP(C13,$R$1:$X$34,_xlfn.IFS(D13=S$1,2,D13=T$1,3,D13=U$1,4,D13=V$1,5,D13=W$1,6,D13=X$1,7),FALSE)} -> 0.027535442 | N13: =J13*M13 -> 27.315158 | R13: 魔晶核包 | S13: =SUMIFS($K:$K,$C:$C,$R13,$D:$D,S$1) -> 0 | T13: =SUMIFS($K:$K,$C:$C,$R13,$D:$D,T$1) -> 1799 | U13: =SUMIFS($K:$K,$C:$C,$R13,$D:$D,U$1) -> 3592 | V13: =SUMIFS($K:$K,$C:$C,$R13,$D:$D,V$1) -> 6401 | W13: =SUMIFS($K:$K,$C:$C,$R13,$D:$D,W$1) -> 6411 | X13: =SUMIFS($K:$K,$C:$C,$R13,$D:$D,X$1) -> 6398
A14: 12 | B14: 1级容器 | C14: 陶罐1 | D14: 白 | E14: 木尺 | F14: =K14 -> 99 | G14: =VLOOKUP(E14,Sheet2!$B:$G,5,FALSE) -> 1 | H14: =VLOOKUP(E14,Sheet2!$B:$G,6,FALSE) -> 1 | I14: =G14*H14 -> 1 | J14: =VLOOKUP(E14,Sheet2!$B:$I,8,FALSE) -> 1006 | K14: {=_xlfn.IFS(D14="白",ROUND(100000/J14,0),D14="绿",ROUND(300000/J14,0),D14="蓝",ROUND(1000000/J14,0),D14="紫",ROUND(3000000/J14,0),D14="金",ROUND(10000000/J14,0),D14="红",ROUND(30000000/J14,0))} -> 99 | L14: =IF(VLOOKUP(E14,Sheet2!$B:$V,21,FALSE)=1,K14,ROUND(K14/2,0)) -> 50 | M14: {=K14/VLOOKUP(C14,$R$1:$X$34,_xlfn.IFS(D14=S$1,2,D14=T$1,3,D14=U$1,4,D14=V$1,5,D14=W$1,6,D14=X$1,7),FALSE)} -> 0.026990185 | N14: =J14*M14 -> 27.152126 | R14: 医疗包 | S14: =SUMIFS($K:$K,$C:$C,$R14,$D:$D,S$1) -> 927 | T14: =SUMIFS($K:$K,$C:$C,$R14,$D:$D,T$1) -> 1353 | U14: =SUMIFS($K:$K,$C:$C,$R14,$D:$D,U$1) -> 1074 | V14: =SUMIFS($K:$K,$C:$C,$R14,$D:$D,V$1) -> 808 | W14: =SUMIFS($K:$K,$C:$C,$R14,$D:$D,W$1) -> 785 | X14: =SUMIFS($K:$K,$C:$C,$R14,$D:$D,X$1) -> 121
... A34: 32 | B34: 1级容器 | C34: 陶罐1 | D34: 白 | E34: 倒吊人之牌 | F34: =K34 -> 100 | G34: =VLOOKUP(E34,Sheet2!$B:$G,5,FALSE) -> 1 | H34: =VLOOKUP(E34,Sheet2!$B:$G,6,FALSE) -> 1 | I34: =G34*H34 -> 1 | J34: =VLOOKUP(E34,Sheet2!$B:$I,8,FALSE) -> 1004 | K34: {=_xlfn.IFS(D34="白",ROUND(100000/J34,0),D34="绿",ROUND(300000/J34,0),D34="蓝",ROUND(1000000/J34,0),D34="紫",ROUND(3000000/J34,0),D34="金",ROUND(10000000/J34,0),D34="红",ROUND(30000000/J34,0))} -> 100 | L34: =IF(VLOOKUP(E34,Sheet2!$B:$V,21,FALSE)=1,K34,ROUND(K34/2,0)) -> 50 | M34: {=K34/VLOOKUP(C34,$R$1:$X$34,_xlfn.IFS(D34=S$1,2,D34=T$1,3,D34=U$1,4,D34=V$1,5,D34=W$1,6,D34=X$1,7),FALSE)} -> 0.027262814 | N34: =J34*M34 -> 27.371865 | R34: 陶罐6 | S34: =SUMIFS($K:$K,$C:$C,$R34,$D:$D,S$1) -> 1949 | T34: =SUMIFS($K:$K,$C:$C,$R34,$D:$D,T$1) -> 4521 | U34: =SUMIFS($K:$K,$C:$C,$R34,$D:$D,U$1) -> 3703 | V34: =SUMIFS($K:$K,$C:$C,$R34,$D:$D,V$1) -> 3490 | W34: =SUMIFS($K:$K,$C:$C,$R34,$D:$D,W$1) -> 3240 | X34: =SUMIFS($K:$K,$C:$C,$R34,$D:$D,X$1) -> 2010
A35: 33 | B35: 1级容器 | C35: 陶罐1 | D35: 白 | E35: 死神之牌 | F35: =K35 -> 101 | G35: =VLOOKUP(E35,Sheet2!$B:$G,5,FALSE) -> 1 | H35: =VLOOKUP(E35,Sheet2!$B:$G,6,FALSE) -> 1 | I35: =G35*H35 -> 1 | J35: =VLOOKUP(E35,Sheet2!$B:$I,8,FALSE) -> 994 | K35: {=_xlfn.IFS(D35="白",ROUND(100000/J35,0),D35="绿",ROUND(300000/J35,0),D35="蓝",ROUND(1000000/J35,0),D35="紫",ROUND(3000000/J35,0),D35="金",ROUND(10000000/J35,0),D35="红",ROUND(30000000/J35,0))} -> 101 | L35: =IF(VLOOKUP(E35,Sheet2!$B:$V,21,FALSE)=1,K35,ROUND(K35/2,0)) -> 51 | M35: {=K35/VLOOKUP(C35,$R$1:$X$34,_xlfn.IFS(D35=S$1,2,D35=T$1,3,D35=U$1,4,D35=V$1,5,D35=W$1,6,D35=X$1,7),FALSE)} -> 0.027535442 | N35: =J35*M35 -> 27.370229 | Y35: 单局 | Z35: {=SUMPRODUCT(Z37:Z68,AA37:AA68)} -> 3206292.4
A36: 34 | B36: 1级容器 | C36: 陶罐1 | D36: 白 | E36: 节制之牌 | F36: =K36 -> 99 | G36: =VLOOKUP(E36,Sheet2!$B:$G,5,FALSE) -> 1 | H36: =VLOOKUP(E36,Sheet2!$B:$G,6,FALSE) -> 1 | I36: =G36*H36 -> 1 | J36: =VLOOKUP(E36,Sheet2!$B:$I,8,FALSE) -> 1009 | K36: {=_xlfn.IFS(D36="白",ROUND(100000/J36,0),D36="绿",ROUND(300000/J36,0),D36="蓝",ROUND(1000000/J36,0),D36="紫",ROUND(3000000/J36,0),D36="金",ROUND(10000000/J36,0),D36="红",ROUND(30000000/J36,0))} -> 99 | L36: =IF(VLOOKUP(E36,Sheet2!$B:$V,21,FALSE)=1,K36,ROUND(K36/2,0)) -> 50 | M36: {=K36/VLOOKUP(C36,$R$1:$X$34,_xlfn.IFS(D36=S$1,2,D36=T$1,3,D36=U$1,4,D36=V$1,5,D36=W$1,6,D36=X$1,7),FALSE)} -> 0.026990185 | N36: =J36*M36 -> 27.233097
A37: 35 | B37: 1级容器 | C37: 陶罐1 | D37: 白 | E37: 恶魔之牌 | F37: =K37 -> 101 | G37: =VLOOKUP(E37,Sheet2!$B:$G,5,FALSE) -> 1 | H37: =VLOOKUP(E37,Sheet2!$B:$G,6,FALSE) -> 1 | I37: =G37*H37 -> 1 | J37: =VLOOKUP(E37,Sheet2!$B:$I,8,FALSE) -> 994 | K37: {=_xlfn.IFS(D37="白",ROUND(100000/J37,0),D37="绿",ROUND(300000/J37,0),D37="蓝",ROUND(1000000/J37,0),D37="紫",ROUND(3000000/J37,0),D37="金",ROUND(10000000/J37,0),D37="红",ROUND(30000000/J37,0))} -> 101 | L37: =IF(VLOOKUP(E37,Sheet2!$B:$V,21,FALSE)=1,K37,ROUND(K37/2,0)) -> 51 | M37: {=K37/VLOOKUP(C37,$R$1:$X$34,_xlfn.IFS(D37=S$1,2,D37=T$1,3,D37=U$1,4,D37=V$1,5,D37=W$1,6,D37=X$1,7),FALSE)} -> 0.027535442 | N37: =J37*M37 -> 27.370229 | R37: 保险柜 | S37: =SUMIFS($N:$N,$C:$C,$R37,$D:$D,S$1) -> 1000.3738 | T37: =SUMIFS($N:$N,$C:$C,$R37,$D:$D,T$1) -> 5454.7461 | U37: =SUMIFS($N:$N,$C:$C,$R37,$D:$D,U$1) -> 11624.651 | V37: =SUMIFS($N:$N,$C:$C,$R37,$D:$D,V$1) -> 45147.449 | W37: =SUMIFS($N:$N,$C:$C,$R37,$D:$D,W$1) -> 138201.25 | X37: =SUMIFS($N:$N,$C:$C,$R37,$D:$D,X$1) -> 583145.04 | Z37: {=SUMPRODUCT(S37:X37,S70:X70)} -> 124304.18 | AA37: 4.5
A38: 36 | B38: 1级容器 | C38: 陶罐1 | D38: 白 | E38: 高塔之牌 | F38: =K38 -> 101 | G38: =VLOOKUP(E38,Sheet2!$B:$G,5,FALSE) -> 1 | H38: =VLOOKUP(E38,Sheet2!$B:$G,6,FALSE) -> 1 | I38: =G38*H38 -> 1 | J38: =VLOOKUP(E38,Sheet2!$B:$I,8,FALSE) -> 992 | K38: {=_xlfn.IFS(D38="白",ROUND(100000/J38,0),D38="绿",ROUND(300000/J38,0),D38="蓝",ROUND(1000000/J38,0),D38="紫",ROUND(3000000/J38,0),D38="金",ROUND(10000000/J38,0),D38="红",ROUND(30000000/J38,0))} -> 101 | L38: =IF(VLOOKUP(E38,Sheet2!$B:$V,21,FALSE)=1,K38,ROUND(K38/2,0)) -> 51 | M38: {=K38/VLOOKUP(C38,$R$1:$X$34,_xlfn.IFS(D38=S$1,2,D38=T$1,3,D38=U$1,4,D38=V$1,5,D38=W$1,6,D38=X$1,7),FALSE)} -> 0.027535442 | N38: =J38*M38 -> 27.315158 | R38: 小保险箱 | S38: =SUMIFS($N:$N,$C:$C,$R38,$D:$D,S$1) -> 999.9188 | T38: =SUMIFS($N:$N,$C:$C,$R38,$D:$D,T$1) -> 4052.3064 | U38: =SUMIFS($N:$N,$C:$C,$R38,$D:$D,U$1) -> 13548.313 | V38: =SUMIFS($N:$N,$C:$C,$R38,$D:$D,V$1) -> 47987.579 | W38: =SUMIFS($N:$N,$C:$C,$R38,$D:$D,W$1) -> 154434.47 | X38: =SUMIFS($N:$N,$C:$C,$R38,$D:$D,X$1) -> 639305.69 | Z38: {=SUMPRODUCT(S38:X38,S71:X71)} -> 70322.025 | AA38: 5.5
A39: 37 | B39: 1级容器 | C39: 陶罐1 | D39: 白 | E39: 星辰之牌 | F39: =K39 -> 99 | G39: =VLOOKUP(E39,Sheet2!$B:$G,5,FALSE) -> 1 | H39: =VLOOKUP(E39,Sheet2!$B:$G,6,FALSE) -> 1 | I39: =G39*H39 -> 1 | J39: =VLOOKUP(E39,Sheet2!$B:$I,8,FALSE) -> 1010 | K39: {=_xlfn.IFS(D39="白",ROUND(100000/J39,0),D39="绿",ROUND(300000/J39,0),D39="蓝",ROUND(1000000/J39,0),D39="紫",ROUND(3000000/J39,0),D39="金",ROUND(10000000/J39,0),D39="红",ROUND(30000000/J39,0))} -> 99 | L39: =IF(VLOOKUP(E39,Sheet2!$B:$V,21,FALSE)=1,K39,ROUND(K39/2,0)) -> 50 | M39: {=K39/VLOOKUP(C39,$R$1:$X$34,_xlfn.IFS(D39=S$1,2,D39=T$1,3,D39=U$1,4,D39=V$1,5,D39=W$1,6,D39=X$1,7),FALSE)} -> 0.026990185 | N39: =J39*M39 -> 27.260087 | R39: 魔法仪器 | S39: =SUMIFS($N:$N,$C:$C,$R39,$D:$D,S$1) -> 1318.4737 | T39: =SUMIFS($N:$N,$C:$C,$R39,$D:$D,T$1) -> 4441.7376 | U39: =SUMIFS($N:$N,$C:$C,$R39,$D:$D,U$1) -> 14790.847 | V39: =SUMIFS($N:$N,$C:$C,$R39,$D:$D,V$1) -> 36618.377 | W39: =SUMIFS($N:$N,$C:$C,$R39,$D:$D,W$1) -> 131646.4 | X39: =SUMIFS($N:$N,$C:$C,$R39,$D:$D,X$1) -> 408191.31 | Z39: {=SUMPRODUCT(S39:X39,S72:X72)} -> 73423.13 | AA39: 0
A40: 38 | B40: 1级容器 | C40: 陶罐1 | D40: 白 | E40: 月亮之牌 | F40: =K40 -> 99 | G40: =VLOOKUP(E40,Sheet2!$B:$G,5,FALSE) -> 1 | H40: =VLOOKUP(E40,Sheet2!$B:$G,6,FALSE) -> 1 | I40: =G40*H40 -> 1 | J40: =VLOOKUP(E40,Sheet2!$B:$I,8,FALSE) -> 1008 | K40: {=_xlfn.IFS(D40="白",ROUND(100000/J40,0),D40="绿",ROUND(300000/J40,0),D40="蓝",ROUND(1000000/J40,0),D40="紫",ROUND(3000000/J40,0),D40="金",ROUND(10000000/J40,0),D40="红",ROUND(30000000/J40,0))} -> 99 | L40: =IF(VLOOKUP(E40,Sheet2!$B:$V,21,FALSE)=1,K40,ROUND(K40/2,0)) -> 50 | M40: {=K40/VLOOKUP(C40,$R$1:$X$34,_xlfn.IFS(D40=S$1,2,D40=T$1,3,D40=U$1,4,D40=V$1,5,D40=W$1,6,D40=X$1,7),FALSE)} -> 0.026990185 | N40: =J40*M40 -> 27.206107 | R40: 高级储物箱 | S40: =SUMIFS($N:$N,$C:$C,$R40,$D:$D,S$1) -> 1380.6089 | T40: =SUMIFS($N:$N,$C:$C,$R40,$D:$D,T$1) -> 4480.311 | U40: =SUMIFS($N:$N,$C:$C,$R40,$D:$D,U$1) -> 14646.155 | V40: =SUMIFS($N:$N,$C:$C,$R40,$D:$D,V$1) -> 49248.998 | W40: =SUMIFS($N:$N,$C:$C,$R40,$D:$D,W$1) -> 164341.58 | X40: =SUMIFS($N:$N,$C:$C,$R40,$D:$D,X$1) -> 667238.65 | Z40: {=SUMPRODUCT(S40:X40,S73:X73)} -> 36359.456 | AA40: 8.5
A41: 39 | B41: 1级容器 | C41: 陶罐1 | D41: 白 | E41: 太阳之牌 | F41: =K41 -> 100 | G41: =VLOOKUP(E41,Sheet2!$B:$G,5,FALSE) -> 1 | H41: =VLOOKUP(E41,Sheet2!$B:$G,6,FALSE) -> 1 | I41: =G41*H41 -> 1 | J41: =VLOOKUP(E41,Sheet2!$B:$I,8,FALSE) -> 999 | K41: {=_xlfn.IFS(D41="白",ROUND(100000/J41,0),D41="绿",ROUND(300000/J41,0),D41="蓝",ROUND(1000000/J41,0),D41="紫",ROUND(3000000/J41,0),D41="金",ROUND(10000000/J41,0),D41="红",ROUND(30000000/J41,0))} -> 100 | L41: =IF(VLOOKUP(E41,Sheet2!$B:$V,21,FALSE)=1,K41,ROUND(K41/2,0)) -> 50 | M41: {=K41/VLOOKUP(C41,$R$1:$X$34,_xlfn.IFS(D41=S$1,2,D41=T$1,3,D41=U$1,4,D41=V$1,5,D41=W$1,6,D41=X$1,7),FALSE)} -> 0.027262814 | N41: =J41*M41 -> 27.235551 | R41: 高级旅行包 | S41: =SUMIFS($N:$N,$C:$C,$R41,$D:$D,S$1) -> 1105.5236 | T41: =SUMIFS($N:$N,$C:$C,$R41,$D:$D,T$1) -> 4590.6089 | U41: =SUMIFS($N:$N,$C:$C,$R41,$D:$D,U$1) -> 12005.858 | V41: =SUMIFS($N:$N,$C:$C,$R41,$D:$D,V$1) -> 40654.834 | W41: =SUMIFS($N:$N,$C:$C,$R41,$D:$D,W$1) -> 134091.47 | X41: =SUMIFS($N:$N,$C:$C,$R41,$D:$D,X$1) -> 549293.13 | Z41: {=SUMPRODUCT(S41:X41,S74:X74)} -> 32715.968 | AA41: 0
A42: 40 | B42: 1级容器 | C42: 陶罐1 | D42: 白 | E42: 审判之牌 | F42: =K42 -> 100 | G42: =VLOOKUP(E42,Sheet2!$B:$G,5,FALSE) -> 1 | H42: =VLOOKUP(E42,Sheet2!$B:$G,6,FALSE) -> 1 | I42: =G42*H42 -> 1 | J42: =VLOOKUP(E42,Sheet2!$B:$I,8,FALSE) -> 1004 | K42: {=_xlfn.IFS(D42="白",ROUND(100000/J42,0),D42="绿",ROUND(300000/J42,0),D42="蓝",ROUND(1000000/J42,0),D42="紫",ROUND(3000000/J42,0),D42="金",ROUND(10000000/J42,0),D42="红",ROUND(30000000/J42,0))} -> 100 | L42: =IF(VLOOKUP(E42,Sheet2!$B:$V,21,FALSE)=1,K42,ROUND(K42/2,0)) -> 50 | M42: {=K42/VLOOKUP(C42,$R$1:$X$34,_xlfn.IFS(D42=S$1,2,D42=T$1,3,D42=U$1,4,D42=V$1,5,D42=W$1,6,D42=X$1,7),FALSE)} -> 0.027262814 | N42: =J42*M42 -> 27.371865 | R42: 魔法材料柜 | S42: =SUMIFS($N:$N,$C:$C,$R42,$D:$D,S$1) -> 990 | T42: =SUMIFS($N:$N,$C:$C,$R42,$D:$D,T$1) -> 3124.3724 | U42: =SUMIFS($N:$N,$C:$C,$R42,$D:$D,U$1) -> 14581.847 | V42: =SUMIFS($N:$N,$C:$C,$R42,$D:$D,V$1) -> 59763.372 | W42: =SUMIFS($N:$N,$C:$C,$R42,$D:$D,W$1) -> 241739.81 | X42: =SUMIFS($N:$N,$C:$C,$R42,$D:$D,X$1) -> 1008956.7 | Z42: {=SUMPRODUCT(S42:X42,S75:X75)} -> 43134.062 | AA42: 0
A43: 41 | B43: 1级容器 | C43: 陶罐1 | D43: 白 | E43: 世界之牌 | F43: =K43 -> 99 | G43: =VLOOKUP(E43,Sheet2!$B:$G,5,FALSE) -> 1 | H43: =VLOOKUP(E43,Sheet2!$B:$G,6,FALSE) -> 1 | I43: =G43*H43 -> 1 | J43: =VLOOKUP(E43,Sheet2!$B:$I,8,FALSE) -> 1007 | K43: {=_xlfn.IFS(D43="白",ROUND(100000/J43,0),D43="绿",ROUND(300000/J43,0),D43="蓝",ROUND(1000000/J43,0),D43="紫",ROUND(3000000/J43,0),D43="金",ROUND(10000000/J43,0),D43="红",ROUND(30000000/J43,0))} -> 99 | L43: =IF(VLOOKUP(E43,Sheet2!$B:$V,21,FALSE)=1,K43,ROUND(K43/2,0)) -> 50 | M43: {=K43/VLOOKUP(C43,$R$1:$X$34,_xlfn.IFS(D43=S$1,2,D43=T$1,3,D43=U$1,4,D43=V$1,5,D43=W$1,6,D43=X$1,7),FALSE)} -> 0.026990185 | N43: =J43*M43 -> 27.179117 | R43: 魔晶核箱 | S43: =SUMIFS($N:$N,$C:$C,$R43,$D:$D,S$1) -> 6986.94 | T43: =SUMIFS($N:$N,$C:$C,$R43,$D:$D,T$1) -> 3947.703 | U43: =SUMIFS($N:$N,$C:$C,$R43,$D:$D,U$1) -> 6609.204 | V43: =SUMIFS($N:$N,$C:$C,$R43,$D:$D,V$1) -> 17748.147 | W43: =SUMIFS($N:$N,$C:$C,$R43,$D:$D,W$1) -> 59106.138 | X43: =SUMIFS($N:$N,$C:$C,$R43,$D:$D,X$1) -> 177446.07 | Z43: {=SUMPRODUCT(S43:X43,S76:X76)} -> 20433.506 | AA43: 0
A44: 42 | B44: 1级容器 | C44: 陶罐1 | D44: 绿 | E44: 草本药液 | F44: =K44 -> 101 | G44: =VLOOKUP(E44,Sheet2!$B:$G,5,FALSE) -> 1 | H44: =VLOOKUP(E44,Sheet2!$B:$G,6,FALSE) -> 1 | I44: =G44*H44 -> 1 | J44: =VLOOKUP(E44,Sheet2!$B:$I,8,FALSE) -> 2972 | K44: {=_xlfn.IFS(D44="白",ROUND(100000/J44,0),D44="绿",ROUND(300000/J44,0),D44="蓝",ROUND(1000000/J44,0),D44="紫",ROUND(3000000/J44,0),D44="金",ROUND(10000000/J44,0),D44="红",ROUND(30000000/J44,0))} -> 101 | L44: =IF(VLOOKUP(E44,Sheet2!$B:$V,21,FALSE)=1,K44,ROUND(K44/2,0)) -> 51 | M44: {=K44/VLOOKUP(C44,$R$1:$X$34,_xlfn.IFS(D44=S$1,2,D44=T$1,3,D44=U$1,4,D44=V$1,5,D44=W$1,6,D44=X$1,7),FALSE)} -> 0.025287932 | N44: =J44*M44 -> 75.155734 | R44: 医疗箱 | S44: =SUMIFS($N:$N,$C:$C,$R44,$D:$D,S$1) -> 1079.5771 | T44: =SUMIFS($N:$N,$C:$C,$R44,$D:$D,T$1) -> 3105.9667 | U44: =SUMIFS($N:$N,$C:$C,$R44,$D:$D,U$1) -> 12113.773 | V44: =SUMIFS($N:$N,$C:$C,$R44,$D:$D,V$1) -> 40713.671 | W44: =SUMIFS($N:$N,$C:$C,$R44,$D:$D,W$1) -> 178310.1 | X44: =SUMIFS($N:$N,$C:$C,$R44,$D:$D,X$1) -> 1492093.1 | Z44: {=SUMPRODUCT(S44:X44,S77:X77)} -> 35508.986 | AA44: 0
A45: 43 | B45: 1级容器 | C45: 陶罐1 | D45: 绿 | E45: 迅影兔腿 | F45: =K45 -> 100 | G45: =VLOOKUP(E45,Sheet2!$B:$G,5,FALSE) -> 1 | H45: =VLOOKUP(E45,Sheet2!$B:$G,6,FALSE) -> 1 | I45: =G45*H45 -> 1 | J45: =VLOOKUP(E45,Sheet2!$B:$I,8,FALSE) -> 3011 | K45: {=_xlfn.IFS(D45="白",ROUND(100000/J45,0),D45="绿",ROUND(300000/J45,0),D45="蓝",ROUND(1000000/J45,0),D45="紫",ROUND(3000000/J45,0),D45="金",ROUND(10000000/J45,0),D45="红",ROUND(30000000/J45,0))} -> 100 | L45: =IF(VLOOKUP(E45,Sheet2!$B:$V,21,FALSE)=1,K45,ROUND(K45/2,0)) -> 50 | M45: {=K45/VLOOKUP(C45,$R$1:$X$34,_xlfn.IFS(D45=S$1,2,D45=T$1,3,D45=U$1,4,D45=V$1,5,D45=W$1,6,D45=X$1,7),FALSE)} -> 0.025037556 | N45: =J45*M45 -> 75.388082 | R45: 手提箱 | S45: =SUMIFS($N:$N,$C:$C,$R45,$D:$D,S$1) -> 1105.5236 | T45: =SUMIFS($N:$N,$C:$C,$R45,$D:$D,T$1) -> 4590.6089 | U45: =SUMIFS($N:$N,$C:$C,$R45,$D:$D,U$1) -> 12005.858 | V45: =SUMIFS($N:$N,$C:$C,$R45,$D:$D,V$1) -> 40654.834 | W45: =SUMIFS($N:$N,$C:$C,$R45,$D:$D,W$1) -> 134091.47 | X45: =SUMIFS($N:$N,$C:$C,$R45,$D:$D,X$1) -> 549293.13 | Z45: {=SUMPRODUCT(S45:X45,S78:X78)} -> 19098.92 | AA45: 0
A46: 44 | B46: 1级容器 | C46: 陶罐1 | D46: 绿 | E46: 巨龟甲壳 | F46: =K46 -> 101 | G46: =VLOOKUP(E46,Sheet2!$B:$G,5,FALSE) -> 1 | H46: =VLOOKUP(E46,Sheet2!$B:$G,6,FALSE) -> 1 | I46: =G46*H46 -> 1 | J46: =VLOOKUP(E46,Sheet2!$B:$I,8,FALSE) -> 2971 | K46: {=_xlfn.IFS(D46="白",ROUND(100000/J46,0),D46="绿",ROUND(300000/J46,0),D46="蓝",ROUND(1000000/J46,0),D46="紫",ROUND(3000000/J46,0),D46="金",ROUND(10000000/J46,0),D46="红",ROUND(30000000/J46,0))} -> 101 | L46: =IF(VLOOKUP(E46,Sheet2!$B:$V,21,FALSE)=1,K46,ROUND(K46/2,0)) -> 51 | M46: {=K46/VLOOKUP(C46,$R$1:$X$34,_xlfn.IFS(D46=S$1,2,D46=T$1,3,D46=U$1,4,D46=V$1,5,D46=W$1,6,D46=X$1,7),FALSE)} -> 0.025287932 | N46: =J46*M46 -> 75.130446 | R46: 武器箱 | S46: =SUMIFS($N:$N,$C:$C,$R46,$D:$D,S$1) -> 6986.94 | T46: =SUMIFS($N:$N,$C:$C,$R46,$D:$D,T$1) -> 3947.703 | U46: =SUMIFS($N:$N,$C:$C,$R46,$D:$D,U$1) -> 6609.204 | V46: =SUMIFS($N:$N,$C:$C,$R46,$D:$D,V$1) -> 17748.147 | W46: =SUMIFS($N:$N,$C:$C,$R46,$D:$D,W$1) -> 59106.138 | X46: =SUMIFS($N:$N,$C:$C,$R46,$D:$D,X$1) -> 177446.07 | Z46: {=SUMPRODUCT(S46:X46,S79:X79)} -> 14457.815 | AA46: 11.5
A47: 45 | B47: 1级容器 | C47: 陶罐1 | D47: 绿 | E47: 幽冥狼牙 | F47: =K47 -> 100 | G47: =VLOOKUP(E47,Sheet2!$B:$G,5,FALSE) -> 1 | H47: =VLOOKUP(E47,Sheet2!$B:$G,6,FALSE) -> 1 | I47: =G47*H47 -> 1 | J47: =VLOOKUP(E47,Sheet2!$B:$I,8,FALSE) -> 2995 | K47: {=_xlfn.IFS(D47="白",ROUND(100000/J47,0),D47="绿",ROUND(300000/J47,0),D47="蓝",ROUND(1000000/J47,0),D47="紫",ROUND(3000000/J47,0),D47="金",ROUND(10000000/J47,0),D47="红",ROUND(30000000/J47,0))} -> 100 | L47: =IF(VLOOKUP(E47,Sheet2!$B:$V,21,FALSE)=1,K47,ROUND(K47/2,0)) -> 50 | M47: {=K47/VLOOKUP(C47,$R$1:$X$34,_xlfn.IFS(D47=S$1,2,D47=T$1,3,D47=U$1,4,D47=V$1,5,D47=W$1,6,D47=X$1,7),FALSE)} -> 0.025037556 | N47: =J47*M47 -> 74.987481 | R47: 魔晶核包 | S47: =SUMIFS($N:$N,$C:$C,$R47,$D:$D,S$1) -> 0 | T47: =SUMIFS($N:$N,$C:$C,$R47,$D:$D,T$1) -> 3001.4425 | U47: =SUMIFS($N:$N,$C:$C,$R47,$D:$D,U$1) -> 5007.3243 | V47: =SUMIFS($N:$N,$C:$C,$R47,$D:$D,V$1) -> 14999.681 | W47: =SUMIFS($N:$N,$C:$C,$R47,$D:$D,W$1) -> 49946.616 | X47: =SUMIFS($N:$N,$C:$C,$R47,$D:$D,X$1) -> 150076.83 | Z47: {=SUMPRODUCT(S47:X47,S80:X80)} -> 12486.874 | AA47: 12
A48: 46 | B48: 1级容器 | C48: 陶罐1 | D48: 绿 | E48: 岩犀甲皮屑 | F48: =K48 -> 101 | G48: =VLOOKUP(E48,Sheet2!$B:$G,5,FALSE) -> 1 | H48: =VLOOKUP(E48,Sheet2!$B:$G,6,FALSE) -> 1 | I48: =G48*H48 -> 1 | J48: =VLOOKUP(E48,Sheet2!$B:$I,8,FALSE) -> 2975 | K48: {=_xlfn.IFS(D48="白",ROUND(100000/J48,0),D48="绿",ROUND(300000/J48,0),D48="蓝",ROUND(1000000/J48,0),D48="紫",ROUND(3000000/J48,0),D48="金",ROUND(10000000/J48,0),D48="红",ROUND(30000000/J48,0))} -> 101 | L48: =IF(VLOOKUP(E48,Sheet2!$B:$V,21,FALSE)=1,K48,ROUND(K48/2,0)) -> 51 | M48: {=K48/VLOOKUP(C48,$R$1:$X$34,_xlfn.IFS(D48=S$1,2,D48=T$1,3,D48=U$1,4,D48=V$1,5,D48=W$1,6,D48=X$1,7),FALSE)} -> 0.025287932 | N48: =J48*M48 -> 75.231597 | R48: 医疗包 | S48: =SUMIFS($N:$N,$C:$C,$R48,$D:$D,S$1) -> 1079.5771 | T48: =SUMIFS($N:$N,$C:$C,$R48,$D:$D,T$1) -> 3105.9667 | U48: =SUMIFS($N:$N,$C:$C,$R48,$D:$D,U$1) -> 12113.773 | V48: =SUMIFS($N:$N,$C:$C,$R48,$D:$D,V$1) -> 40713.671 | W48: =SUMIFS($N:$N,$C:$C,$R48,$D:$D,W$1) -> 178310.1 | X48: =SUMIFS($N:$N,$C:$C,$R48,$D:$D,X$1) -> 1492093.1 | Z48: {=SUMPRODUCT(S48:X48,S81:X81)} -> 17478.975 | AA48: 5
... A68: 66 | B68: 1级容器 | C68: 陶罐1 | D68: 绿 | E68: 低级能量瓶 | F68: =K68 -> 52 | G68: =VLOOKUP(E68,Sheet2!$B:$G,5,FALSE) -> 1 | H68: =VLOOKUP(E68,Sheet2!$B:$G,6,FALSE) -> 2 | I68: =G68*H68 -> 2 | J68: =VLOOKUP(E68,Sheet2!$B:$I,8,FALSE) -> 5795 | K68: {=_xlfn.IFS(D68="白",ROUND(100000/J68,0),D68="绿",ROUND(300000/J68,0),D68="蓝",ROUND(1000000/J68,0),D68="紫",ROUND(3000000/J68,0),D68="金",ROUND(10000000/J68,0),D68="红",ROUND(30000000/J68,0))} -> 52 | L68: =IF(VLOOKUP(E68,Sheet2!$B:$V,21,FALSE)=1,K68,ROUND(K68/2,0)) -> 26 | M68: {=K68/VLOOKUP(C68,$R$1:$X$34,_xlfn.IFS(D68=S$1,2,D68=T$1,3,D68=U$1,4,D68=V$1,5,D68=W$1,6,D68=X$1,7),FALSE)} -> 0.013019529 | N68: =J68*M68 -> 75.448172 | R68: 陶罐6 | S68: =SUMIFS($N:$N,$C:$C,$R68,$D:$D,S$1) -> 1334.9451 | T68: =SUMIFS($N:$N,$C:$C,$R68,$D:$D,T$1) -> 3845.841 | U68: =SUMIFS($N:$N,$C:$C,$R68,$D:$D,U$1) -> 13782.174 | V68: =SUMIFS($N:$N,$C:$C,$R68,$D:$D,V$1) -> 47211.62 | W68: =SUMIFS($N:$N,$C:$C,$R68,$D:$D,W$1) -> 166960.5 | X68: =SUMIFS($N:$N,$C:$C,$R68,$D:$D,X$1) -> 747824.97 | Z68: {=SUMPRODUCT(S68:X68,S101:X101)} -> 9051.2608 | AA68: 2
A69: 67 | B69: 1级容器 | C69: 陶罐1 | D69: 绿 | E69: 材料包 | F69: =K69 -> 51 | G69: =VLOOKUP(E69,Sheet2!$B:$G,5,FALSE) -> 2 | H69: =VLOOKUP(E69,Sheet2!$B:$G,6,FALSE) -> 1 | I69: =G69*H69 -> 2 | J69: =VLOOKUP(E69,Sheet2!$B:$I,8,FALSE) -> 5832 | K69: {=_xlfn.IFS(D69="白",ROUND(100000/J69,0),D69="绿",ROUND(300000/J69,0),D69="蓝",ROUND(1000000/J69,0),D69="紫",ROUND(3000000/J69,0),D69="金",ROUND(10000000/J69,0),D69="红",ROUND(30000000/J69,0))} -> 51 | L69: =IF(VLOOKUP(E69,Sheet2!$B:$V,21,FALSE)=1,K69,ROUND(K69/2,0)) -> 26 | M69: {=K69/VLOOKUP(C69,$R$1:$X$34,_xlfn.IFS(D69=S$1,2,D69=T$1,3,D69=U$1,4,D69=V$1,5,D69=W$1,6,D69=X$1,7),FALSE)} -> 0.012769154 | N69: =J69*M69 -> 74.469705
A70: 68 | B70: 1级容器 | C70: 陶罐1 | D70: 绿 | E70: 熟铁盔壳 | F70: =K70 -> 52 | G70: =VLOOKUP(E70,Sheet2!$B:$G,5,FALSE) -> 2 | H70: =VLOOKUP(E70,Sheet2!$B:$G,6,FALSE) -> 1 | I70: =G70*H70 -> 2 | J70: =VLOOKUP(E70,Sheet2!$B:$I,8,FALSE) -> 5812 | K70: {=_xlfn.IFS(D70="白",ROUND(100000/J70,0),D70="绿",ROUND(300000/J70,0),D70="蓝",ROUND(1000000/J70,0),D70="紫",ROUND(3000000/J70,0),D70="金",ROUND(10000000/J70,0),D70="红",ROUND(30000000/J70,0))} -> 52 | L70: =IF(VLOOKUP(E70,Sheet2!$B:$V,21,FALSE)=1,K70,ROUND(K70/2,0)) -> 26 | M70: {=K70/VLOOKUP(C70,$R$1:$X$34,_xlfn.IFS(D70=S$1,2,D70=T$1,3,D70=U$1,4,D70=V$1,5,D70=W$1,6,D70=X$1,7),FALSE)} -> 0.013019529 | N70: =J70*M70 -> 75.669504 | R70: 保险柜 | S70: 0 | T70: 0.136 | U70: 0.4264 | V70: 1.04038 | W70: 0.3596 | X70: 0.03762
A71: 69 | B71: 1级容器 | C71: 陶罐1 | D71: 绿 | E71: 裁布剪 | F71: =K71 -> 99 | G71: =VLOOKUP(E71,Sheet2!$B:$G,5,FALSE) -> 1 | H71: =VLOOKUP(E71,Sheet2!$B:$G,6,FALSE) -> 1 | I71: =G71*H71 -> 1 | J71: =VLOOKUP(E71,Sheet2!$B:$I,8,FALSE) -> 3020 | K71: {=_xlfn.IFS(D71="白",ROUND(100000/J71,0),D71="绿",ROUND(300000/J71,0),D71="蓝",ROUND(1000000/J71,0),D71="紫",ROUND(3000000/J71,0),D71="金",ROUND(10000000/J71,0),D71="红",ROUND(30000000/J71,0))} -> 99 | L71: =IF(VLOOKUP(E71,Sheet2!$B:$V,21,FALSE)=1,K71,ROUND(K71/2,0)) -> 50 | M71: {=K71/VLOOKUP(C71,$R$1:$X$34,_xlfn.IFS(D71=S$1,2,D71=T$1,3,D71=U$1,4,D71=V$1,5,D71=W$1,6,D71=X$1,7),FALSE)} -> 0.024787181 | N71: =J71*M71 -> 74.857286 | R71: 小保险箱 | S71: 0.0544 | T71: 0.4136 | U71: 0.806 | V71: 0.56762 | W71: 0.14606 | X71: 0.01232
A72: 70 | B72: 1级容器 | C72: 陶罐1 | D72: 绿 | E72: 熟铁镶框 | F72: =K72 -> 52 | G72: =VLOOKUP(E72,Sheet2!$B:$G,5,FALSE) -> 2 | H72: =VLOOKUP(E72,Sheet2!$B:$G,6,FALSE) -> 1 | I72: =G72*H72 -> 2 | J72: =VLOOKUP(E72,Sheet2!$B:$I,8,FALSE) -> 5806 | K72: {=_xlfn.IFS(D72="白",ROUND(100000/J72,0),D72="绿",ROUND(300000/J72,0),D72="蓝",ROUND(1000000/J72,0),D72="紫",ROUND(3000000/J72,0),D72="金",ROUND(10000000/J72,0),D72="红",ROUND(30000000/J72,0))} -> 52 | L72: =IF(VLOOKUP(E72,Sheet2!$B:$V,21,FALSE)=1,K72,ROUND(K72/2,0)) -> 26 | M72: {=K72/VLOOKUP(C72,$R$1:$X$34,_xlfn.IFS(D72=S$1,2,D72=T$1,3,D72=U$1,4,D72=V$1,5,D72=W$1,6,D72=X$1,7),FALSE)} -> 0.013019529 | N72: =J72*M72 -> 75.591387 | R72: 魔法仪器 | S72: 0 | T72: 0 | U72: 0 | V72: 0.7 | W72: 0.27 | X72: 0.03
A73: 71 | B73: 1级容器 | C73: 陶罐1 | D73: 绿 | E73: 熟铁甲板 | F73: =K73 -> 27 | G73: =VLOOKUP(E73,Sheet2!$B:$G,5,FALSE) -> 2 | H73: =VLOOKUP(E73,Sheet2!$B:$G,6,FALSE) -> 2 | I73: =G73*H73 -> 4 | J73: =VLOOKUP(E73,Sheet2!$B:$I,8,FALSE) -> 10956 | K73: {=_xlfn.IFS(D73="白",ROUND(100000/J73,0),D73="绿",ROUND(300000/J73,0),D73="蓝",ROUND(1000000/J73,0),D73="紫",ROUND(3000000/J73,0),D73="金",ROUND(10000000/J73,0),D73="红",ROUND(30000000/J73,0))} -> 27 | L73: =IF(VLOOKUP(E73,Sheet2!$B:$V,21,FALSE)=1,K73,ROUND(K73/2,0)) -> 14 | M73: {=K73/VLOOKUP(C73,$R$1:$X$34,_xlfn.IFS(D73=S$1,2,D73=T$1,3,D73=U$1,4,D73=V$1,5,D73=W$1,6,D73=X$1,7),FALSE)} -> 0.0067601402 | N73: =J73*M73 -> 74.064096 | R73: 高级储物箱 | S73: 0.2416 | T73: 0.8264 | U73: 0.649 | V73: 0.222278 | W73: 0.05696 | X73: 0.003762
A74: 72 | B74: 1级容器 | C74: 陶罐1 | D74: 绿 | E74: 铁矿 | F74: =K74 -> 100 | G74: =VLOOKUP(E74,Sheet2!$B:$G,5,FALSE) -> 1 | H74: =VLOOKUP(E74,Sheet2!$B:$G,6,FALSE) -> 1 | I74: =G74*H74 -> 1 | J74: =VLOOKUP(E74,Sheet2!$B:$I,8,FALSE) -> 3007 | K74: {=_xlfn.IFS(D74="白",ROUND(100000/J74,0),D74="绿",ROUND(300000/J74,0),D74="蓝",ROUND(1000000/J74,0),D74="紫",ROUND(3000000/J74,0),D74="金",ROUND(10000000/J74,0),D74="红",ROUND(30000000/J74,0))} -> 100 | L74: =IF(VLOOKUP(E74,Sheet2!$B:$V,21,FALSE)=1,K74,ROUND(K74/2,0)) -> 50 | M74: {=K74/VLOOKUP(C74,$R$1:$X$34,_xlfn.IFS(D74=S$1,2,D74=T$1,3,D74=U$1,4,D74=V$1,5,D74=W$1,6,D74=X$1,7),FALSE)} -> 0.025037556 | N74: =J74*M74 -> 75.287932 | R74: 高级旅行包 | S74: 0.5416 | T74: 0.9764 | U74: 0.684 | V74: 0.236728 | W74: 0.05746 | X74: 0.003812
A75: 73 | B75: 1级容器 | C75: 陶罐1 | D75: 绿 | E75: 残痕矿坯 | F75: =K75 -> 52 | G75: =VLOOKUP(E75,Sheet2!$B:$G,5,FALSE) -> 2 | H75: =VLOOKUP(E75,Sheet2!$B:$G,6,FALSE) -> 1 | I75: =G75*H75 -> 2 | J75: =VLOOKUP(E75,Sheet2!$B:$I,8,FALSE) -> 5785 | K75: {=_xlfn.IFS(D75="白",ROUND(100000/J75,0),D75="绿",ROUND(300000/J75,0),D75="蓝",ROUND(1000000/J75,0),D75="紫",ROUND(3000000/J75,0),D75="金",ROUND(10000000/J75,0),D75="红",ROUND(30000000/J75,0))} -> 52 | L75: =IF(VLOOKUP(E75,Sheet2!$B:$V,21,FALSE)=1,K75,ROUND(K75/2,0)) -> 26 | M75: {=K75/VLOOKUP(C75,$R$1:$X$34,_xlfn.IFS(D75=S$1,2,D75=T$1,3,D75=U$1,4,D75=V$1,5,D75=W$1,6,D75=X$1,7),FALSE)} -> 0.013019529 | N75: =J75*M75 -> 75.317977 | R75: 魔法材料柜 | S75: 0.2416 | T75: 0.8264 | U75: 0.649 | V75: 0.222278 | W75: 0.05696 | X75: 0.003762
A76: 74 | B76: 1级容器 | C76: 陶罐1 | D76: 绿 | E76: 岩纹原岩料 | F76: =K76 -> 100 | G76: =VLOOKUP(E76,Sheet2!$B:$G,5,FALSE) -> 1 | H76: =VLOOKUP(E76,Sheet2!$B:$G,6,FALSE) -> 1 | I76: =G76*H76 -> 1 | J76: =VLOOKUP(E76,Sheet2!$B:$I,8,FALSE) -> 3014 | K76: {=_xlfn.IFS(D76="白",ROUND(100000/J76,0),D76="绿",ROUND(300000/J76,0),D76="蓝",ROUND(1000000/J76,0),D76="紫",ROUND(3000000/J76,0),D76="金",ROUND(10000000/J76,0),D76="红",ROUND(30000000/J76,0))} -> 100 | L76: =IF(VLOOKUP(E76,Sheet2!$B:$V,21,FALSE)=1,K76,ROUND(K76/2,0)) -> 50 | M76: {=K76/VLOOKUP(C76,$R$1:$X$34,_xlfn.IFS(D76=S$1,2,D76=T$1,3,D76=U$1,4,D76=V$1,5,D76=W$1,6,D76=X$1,7),FALSE)} -> 0.025037556 | N76: =J76*M76 -> 75.463195 | R76: 魔晶核箱 | S76: 0.5416 | T76: 0.9764 | U76: 0.684 | V76: 0.236728 | W76: 0.05746 | X76: 0.003812
A77: 75 | B77: 1级容器 | C77: 陶罐1 | D77: 绿 | E77: 高原锰石 | F77: =K77 -> 100 | G77: =VLOOKUP(E77,Sheet2!$B:$G,5,FALSE) -> 1 | H77: =VLOOKUP(E77,Sheet2!$B:$G,6,FALSE) -> 1 | I77: =G77*H77 -> 1 | J77: =VLOOKUP(E77,Sheet2!$B:$I,8,FALSE) -> 2991 | K77: {=_xlfn.IFS(D77="白",ROUND(100000/J77,0),D77="绿",ROUND(300000/J77,0),D77="蓝",ROUND(1000000/J77,0),D77="紫",ROUND(3000000/J77,0),D77="金",ROUND(10000000/J77,0),D77="红",ROUND(30000000/J77,0))} -> 100 | L77: =IF(VLOOKUP(E77,Sheet2!$B:$V,21,FALSE)=1,K77,ROUND(K77/2,0)) -> 50 | M77: {=K77/VLOOKUP(C77,$R$1:$X$34,_xlfn.IFS(D77=S$1,2,D77=T$1,3,D77=U$1,4,D77=V$1,5,D77=W$1,6,D77=X$1,7),FALSE)} -> 0.025037556 | N77: =J77*M77 -> 74.887331 | R77: 医疗箱 | S77: 0.2416 | T77: 0.8264 | U77: 0.649 | V77: 0.222278 | W77: 0.05696 | X77: 0.003762
A78: 76 | B78: 1级容器 | C78: 陶罐1 | D78: 绿 | E78: 赤纹铜矿 | F78: =K78 -> 101 | G78: =VLOOKUP(E78,Sheet2!$B:$G,5,FALSE) -> 1 | H78: =VLOOKUP(E78,Sheet2!$B:$G,6,FALSE) -> 1 | I78: =G78*H78 -> 1 | J78: =VLOOKUP(E78,Sheet2!$B:$I,8,FALSE) -> 2971 | K78: {=_xlfn.IFS(D78="白",ROUND(100000/J78,0),D78="绿",ROUND(300000/J78,0),D78="蓝",ROUND(1000000/J78,0),D78="紫",ROUND(3000000/J78,0),D78="金",ROUND(10000000/J78,0),D78="红",ROUND(30000000/J78,0))} -> 101 | L78: =IF(VLOOKUP(E78,Sheet2!$B:$V,21,FALSE)=1,K78,ROUND(K78/2,0)) -> 51 | M78: {=K78/VLOOKUP(C78,$R$1:$X$34,_xlfn.IFS(D78=S$1,2,D78=T$1,3,D78=U$1,4,D78=V$1,5,D78=W$1,6,D78=X$1,7),FALSE)} -> 0.025287932 | N78: =J78*M78 -> 75.130446 | R78: 手提箱 | S78: 0.928 | T78: 0.956 | U78: 0.4578 | V78: 0.145098 | W78: 0.01182 | X78: 0.001282
...

Sheet Sheet2
A1: 序号 | B1: 物品名称 | C1: 物品分类 | D1: 品质 | E1: 组内序号 | F1: 长 | G1: 宽 | H1: 面积价值衰减 | I1: 初始定价 | J1: 单格价值 | K1: 衰减后单格价值 | L1: 系统回收价(不变) | M1: 价值浮动系数 | N1: 售价下限 | O1: 售价上限 | P1: 最低保证金 | Q1: 价格区间长度 | R1: 道具描述 | S1: 物品id | T1: 面积 | U1: 衰减系数 | AD1: name | AE1: id
L2: 0.6 | M2: ±1.00% | N2: 0.15 | O2: 15 | P2: 0.009 | Q2: 0.0033554795 | AD2: name:string | AE2: id:number
A3: 1 | B3: 远古龙心 | C3: 生物材料 | D3: 红 | E3: 1 | F3: 3 | G3: 3 | H3: 0.8 | I3: 2176697 | J3: 302319 | K3: 241855 | L3: 1306018 | M3: 1.00773 | N3: 326505 | O3: 32650455 | P3: 19590.27 | Q3: 108462 | R3: 仍在微弱跳动的龙之心脏，蕴含庞大生命力，蕴含极致的生命与力量本源。 | S3: 160020043 | T3: 1 | U3: 1 | AE3: -1
A4: 2 | B4: 生命之树精华 | C4: 生物材料 | D4: 红 | E4: 2 | F4: 3 | G4: 3 | H4: 0.8 | I4: 2143325 | J4: 297684 | K4: 238147 | L4: 1285995 | M4: 0.99228 | N4: 321499 | O4: 32149875 | P4: 19289.925 | Q4: 106799 | R4: 从世界树树芯中提取的翠绿色液体，拥有极强的生机修复之力。 | S4: 160020044 | T4: 2 | U4: 0.97 | AD4: 钻石 | AE4: 1
A5: 3 | B5: 龙骨标本 | C5: 生物材料 | D5: 红 | E5: 3 | F5: 2 | G5: 2 | H5: 0.91 | I5: 1096095 | J5: 301125 | K5: 274024 | L5: 657657 | M5: 1.00375 | N5: 164414 | O5: 16441425 | P5: 9864.855 | Q5: 54617 | R5: 保存完好的巨龙骨骼碎片，具备极强的结构稳定性与魔力传导性。 | S5: 160020045 | T5: 3 | U5: 0.94 | AD5: 经验 | AE5: 2
A6: 4 | B6: 不朽之骨 | C6: 生物材料 | D6: 红 | E6: 4 | F6: 2 | G6: 3 | H6: 0.88 | I6: 1570504 | J6: 297444 | K6: 261751 | L6: 942302 | M6: 0.99148 | N6: 235576 | O6: 23557560 | P6: 14134.53 | Q6: 78256 | R6: 来自不死生物的骨骼，带有抗腐与不灭特性。 | S6: 160020046 | T6: 4 | U6: 0.91 | AD6: VIP经验 | AE6: 3
A7: 5 | B7: 神圣羽毛 | C7: 生物材料 | D7: 红 | E7: 5 | F7: 2 | G7: 3 | H7: 0.88 | I7: 1593346 | J7: 301770 | K7: 265558 | L7: 956008 | M7: 1.0059 | N7: 239002 | O7: 23900190 | P7: 14340.12 | Q7: 79395 | R7: 高阶圣兽羽翼脱落之羽，蕴含净化与治愈力量。 | S7: 160020047 | T7: 6 | U7: 0.88 | AD7: 钻石(弃用) | AE7: 10
A8: 6 | B8: 星界灵翼晶核 | C8: 生物材料 | D8: 红 | E8: 6 | F8: 2 | G8: 2 | H8: 0.91 | I8: 1084116 | J8: 297834 | K8: 271029 | L8: 650470 | M8: 0.99278 | N8: 162617 | O8: 16261740 | P8: 9757.05 | Q8: 54020 | R8: 星界灵翼巨兽的核心结晶，封存着纯粹的星界能量，兼具净化与魔力增幅的本源之力。 | S8: 160020048 | T8: 8 | U8: 0.84 | AD8: 金币 | AE8: 11
A9: 7 | B9: 金鳞龙血 | C9: 生物材料 | D9: 金 | E9: 7 | F9: 1 | G9: 1 | H9: 1 | I9: 100388 | J9: 100388 | K9: 100388 | L9: 60233 | M9: 1.00388 | N9: 15058 | O9: 1505820 | P9: 903.495 | Q9: 5002 | R9: 从成年巨龙体内提取的血液，富含高浓度火属性能量。 | S9: 160020037 | T9: 9 | U9: 0.8 | AD9: 改名卡 | AE9: 201
A10: 8 | B10: 月光花蜜 | C10: 生物材料 | D10: 金 | E10: 8 | F10: 1 | G10: 1 | H10: 1 | I10: 99889 | J10: 99889 | K10: 99889 | L10: 59933 | M10: 0.99889 | N10: 14983 | O10: 1498335 | P10: 898.995 | Q10: 4977 | R10: 仅在满月夜采集的花蜜，具有稳定魔力与安神效果。 | S10: 160020036 | T10: 10 | U10: 0.75 | AD10: 新手战备令 | AE10: 1001
A11: 9 | B11: 黑檀木 | C11: 生物材料 | D11: 金 | E11: 9 | F11: 1 | G11: 2 | H11: 0.97 | I11: 195868 | J11: 100963 | K11: 97934 | L11: 117521 | M11: 1.00963 | N11: 29380 | O11: 2938020 | P11: 1762.815 | Q11: 9760 | R11: 质地坚硬如铁的珍稀木料，纹理深邃，是打造高阶器物的良材。 | S11: 160020038 | T11: 12 | U11: 0.7 | AD11: 标准战备令 | AE11: 1002
A12: 10 | B12: 巨蛛毒腺 | C12: 生物材料 | D12: 金 | E12: 10 | F12: 1 | G12: 1 | H12: 1 | I12: 100979 | J12: 100979 | K12: 100979 | L12: 60587 | M12: 1.00979 | N12: 15147 | O12: 1514685 | P12: 908.805 | Q12: 5032 | R12: 大型毒蛛体内的毒素腺体，可用于剧毒或腐蚀配方。 | S12: 160020039 | AD12: 精英战备令 | AE12: 1003
A13: 11 | B13: 森林古鹿之角 | C13: 生物材料 | D13: 金 | E13: 11 | F13: 1 | G13: 2 | H13: 0.97 | I13: 193503 | J13: 99744 | K13: 96752 | L13: 116102 | M13: 0.99744 | N13: 29025 | O13: 2902545 | P13: 1741.53 | Q13: 9642 | R13: 古老灵鹿的分叉鹿角，具有自然恢复与祝福效果。 | S13: 160020040 | AD13: 卫队长 | AE13: 100100
A14: 12 | B14: 渊甲龙鳞 | C14: 生物材料 | D14: 金 | E14: 12 | F14: 2 | G14: 3 | H14: 0.88 | I14: 529172 | J14: 100222 | K14: 88195 | L14: 317503 | M14: 1.00222 | N14: 79376 | O14: 7937580 | P14: 4762.545 | Q14: 26368 | R14: 深渊古龙的鳞甲碎片，质地坚不可摧，自带稳固的守护气息。 | S14: 160020041 | AD14: 暗夜女王 | AE14: 100200
A15: 13 | B15: 炎羽龙皮 | C15: 生物材料 | D15: 金 | E15: 13 | F15: 1 | G15: 2 | H15: 0.97 | I15: 192590 | J15: 99273 | K15: 96295 | L15: 115554 | M15: 0.99273 | N15: 28889 | O15: 2888850 | P15: 1733.31 | Q15: 9597 | R15: 炎翼巨龙的翎羽下皮层，坚韧耐热，蕴含着微弱的炎属性本源。 | S15: 160020042 | AD15: 海潮祭司 | AE15: 100300
A16: 14 | B16: 细密蛛丝 | C16: 生物材料 | D16: 紫 | E16: 14 | F16: 2 | G16: 2 | H16: 0.91 | I16: 109611 | J16: 30113 | K16: 27403 | L16: 65767 | M16: 1.00377 | N16: 16442 | O16: 1644165 | P16: 986.505 | Q16: 5462 | R16: 灵蛛吐出的丝线，纤细却强韧，是制作轻韧装备的优质材料。 | S16: 160020032 | AD16: 蝶女 | AE16: 100400
A17: 15 | B17: 幻角兽血 | C17: 生物材料 | D17: 紫 | E17: 15 | F17: 1 | G17: 1 | H17: 1 | I17: 29773 | J17: 29773 | K17: 29773 | L17: 17864 | M17: 0.99244 | N17: 4466 | O17: 446595 | P17: 267.96 | Q17: 1484 | R17: 幻角异兽体内的精纯血液，生机旺盛，流转着鲜活的生命能量。 | S17: 160020033 | AD17: 虫母 | AE17: 100500
A18: 16 | B18: 岩犀厚甲片 | C18: 生物材料 | D18: 紫 | E18: 16 | F18: 2 | G18: 2 | H18: 0.91 | I18: 109284 | J18: 30023 | K18: 27321 | L18: 65570 | M18: 1.00075 | N18: 16393 | O18: 1639260 | P18: 983.55 | Q18: 5445 | R18: 岩犀体表的厚重甲片，质地坚硬，防御性能出众。 | S18: 160020034 | AD18: 海潮祭司 | AE18: 100600
A19: 17 | B19: 紫杉木 | C19: 生物材料 | D19: 紫 | E19: 17 | F19: 1 | G19: 2 | H19: 0.97 | I19: 58524 | J19: 30167 | K19: 29262 | L19: 35114 | M19: 1.00557 | N19: 8779 | O19: 877860 | P19: 526.71 | Q19: 2916 | R19: 质地坚韧的珍稀木料，弹性极佳，是打造兵器的上佳材料。 | S19: 160020035 | AD19: 雷霆使者 | AE19: 100700
A20: 18 | B20: 韧化藤蔓丝 | C20: 生物材料 | D20: 蓝 | E20: 18 | F20: 1 | G20: 1 | H20: 1 | I20: 9909 | J20: 9909 | K20: 9909 | L20: 5945 | M20: 0.9909 | N20: 1486 | O20: 148635 | P20: 89.175 | Q20: 494 | R20: 经自然之力淬炼的藤蔓纤维，柔韧度远超普通植物纤维。 | S20: 160020022 | AD20: 野蛮人 | AE20: 100800
A21: 19 | B21: 穿山甲鳞甲 | C21: 生物材料 | D21: 蓝 | E21: 19 | F21: 2 | G21: 3 | H21: 0.88 | I21: 53022 | J21: 10042 | K21: 8837 | L21: 31813 | M21: 1.00423 | N21: 7953 | O21: 795330 | P21: 477.195 | Q21: 2642 | R21: 穿山甲的坚硬鳞片，轻薄坚韧，适合制作轻型防护装备。 | S21: 160020023 | AD21: 缚魂灵师 | AE21: 100900
A22: 20 | B22: 硬质橡木 | C22: 生物材料 | D22: 蓝 | E22: 20 | F22: 1 | G22: 2 | H22: 0.97 | I22: 19289 | J22: 9943 | K22: 9645 | L22: 11573 | M22: 0.99429 | N22: 2893 | O22: 289335 | P22: 173.595 | Q22: 961 | R22: 质地密实的普通优质木料，是新手阶段打造装备的常用主材。 | S22: 160020024 | AD22: 猎杀者 | AE22: 101000
A23: 21 | B23: 林地浆果 | C23: 生物材料 | D23: 蓝 | E23: 21 | F23: 1 | G23: 1 | H23: 1 | I23: 9931 | J23: 9931 | K23: 9931 | L23: 5959 | M23: 0.9931 | N23: 1490 | O23: 148965 | P23: 89.385 | Q23: 495 | R23: 林间常见的野生浆果，可作为基础炼药的初级材料。 | S23: 160020025 | AD23: 狼人 | AE23: 101100
... A70: 68 | B70: 麻衣围裙 | C70: 生活物品 | D70: 绿 | E70: 35 | F70: 2 | G70: 2 | H70: 0.91 | I70: 11029 | J70: 3030 | K70: 2757 | L70: 6617 | M70: 1.00985 | N70: 1654 | O70: 165435 | P70: 99.255 | Q70: 550 | R70: 烹饪时穿戴，防止衣物沾染油污。 | S70: 160060015 | AD70: 中通用防具维修 | AE70: 152000002
A71: 69 | B71: 编织草垫 | C71: 生活物品 | D71: 绿 | E71: 36 | F71: 2 | G71: 2 | H71: 0.91 | I71: 10953 | J71: 3009 | K71: 2738 | L71: 6572 | M71: 1.003 | N71: 1643 | O71: 164295 | P71: 98.58 | Q71: 546 | R71: 干草编织而成，可铺垫坐卧，简易实用。 | S71: 160060016 | AD71: 大通用防具维修 | AE71: 152000003 | AF71: 152000003,153010001,153020001,153030001,160010001,160010002
A72: 70 | B72: 食盐 | C72: 生活物品 | D72: 绿 | E72: 37 | F72: 1 | G72: 1 | H72: 1 | I72: 2977 | J72: 2977 | K72: 2977 | L72: 1786 | M72: 0.99218 | N72: 447 | O72: 44655 | P72: 26.79 | Q72: 148 | R72: 基础调味品，提味增鲜，烹饪必备。 | S72: 160060017 | AD72: 地图1测试钥匙 | AE72: 153010001
A73: 71 | B73: 麦香面包 | C73: 生活物品 | D73: 绿 | E73: 38 | F73: 1 | G73: 1 | H73: 1 | I73: 3004 | J73: 3004 | K73: 3004 | L73: 1802 | M73: 1.00125 | N73: 451 | O73: 45060 | P73: 27.03 | Q73: 150 | R73: 基础主食，松软饱腹，日常食用。 | S73: 160060018 | AD73: 地图2测试钥匙 | AE73: 153020001
A74: 72 | B74: 水壶 | C74: 生活物品 | D74: 绿 | E74: 39 | F74: 1 | G74: 1 | H74: 1 | I74: 2980 | J74: 2980 | K74: 2980 | L74: 1788 | M74: 0.99322 | N74: 447 | O74: 44700 | P74: 26.82 | Q74: 148 | R74: 普通盛水器具，用于外出携带饮水。 | S74: 160060019 | AD74: 地图3测试钥匙 | AE74: 153030001
A75: 73 | B75: 淡酒 | C75: 生活物品 | D75: 绿 | E75: 40 | F75: 1 | G75: 2 | H75: 0.97 | I75: 5773 | J75: 2976 | K75: 2887 | L75: 3464 | M75: 0.992 | N75: 866 | O75: 86595 | P75: 51.96 | Q75: 288 | R75: 度数极低的酒液，口感清淡，不易醉人。 | S75: 160060020 | AD75: 青铜矿 | AE75: 160010001
A76: 74 | B76: 擦布 | C76: 生活物品 | D76: 绿 | E76: 41 | F76: 1 | G76: 1 | H76: 1 | I76: 3009 | J76: 3009 | K76: 3009 | L76: 1805 | M76: 1.003 | N76: 451 | O76: 45135 | P76: 27.075 | Q76: 150 | R76: 棉质布料，用于擦拭桌面、餐具。 | S76: 160060021 | AD76: 铁矿 | AE76: 160010002
A77: 75 | B77: 实木餐盘 | C77: 生活物品 | D77: 绿 | E77: 42 | F77: 2 | G77: 2 | H77: 0.91 | I77: 11015 | J77: 3026 | K77: 2754 | L77: 6609 | M77: 1.00875 | N77: 1652 | O77: 165225 | P77: 99.135 | Q77: 549 | R77: 实木制成，用于盛放食物、蔬果。 | S77: 160060022 | AD77: 高原锰石 | AE77: 160010003
A78: 76 | B78: 老旧油灯 | C78: 生活物品 | D78: 绿 | E78: 43 | F78: 2 | G78: 2 | H78: 0.91 | I78: 10949 | J78: 3008 | K78: 2737 | L78: 6569 | M78: 1.00277 | N78: 1642 | O78: 164235 | P78: 98.535 | Q78: 546 | R78: 使用已久的旧油灯，照明效果一般，仍可使用。 | S78: 160060023 | AD78: 赤纹铜矿 | AE78: 160010004
A79: 77 | B79: 杂粮饼干 | C79: 生活物品 | D79: 绿 | E79: 44 | F79: 1 | G79: 1 | H79: 1 | I79: 3002 | J79: 3002 | K79: 3002 | L79: 1801 | M79: 1.00076 | N79: 450 | O79: 45030 | P79: 27.015 | Q79: 150 | R79: 谷物压制的饼食，耐储存，便携充饥。 | S79: 160060024 | AD79: 杂纹彩晶 | AE79: 160010005
A80: 78 | B80: 日晒果干 | C80: 生活物品 | D80: 绿 | E80: 45 | F80: 1 | G80: 1 | H80: 1 | I80: 2970 | J80: 2970 | K80: 2970 | L80: 1782 | M80: 0.99012 | N80: 446 | O80: 44550 | P80: 26.73 | Q80: 148 | R80: 鲜果脱水制成，保留甜味，方便存放食用。 | S80: 160060025 | AD80: 岩纹原岩料 | AE80: 160010006
A81: 79 | B81: 旧油灯 | C81: 生活物品 | D81: 白 | E81: 46 | F81: 2 | G81: 3 | H81: 0.88 | I81: 5232 | J81: 991 | K81: 872 | L81: 3139 | M81: 0.99096 | N81: 785 | O81: 78480 | P81: 47.085 | Q81: 261 | R81: 灯身布满烟熏痕迹与斑驳锈迹，灯芯焦枯蜷曲，散发出陈旧而暗沉的油烟气息。 | S81: 160060001 | AD81: 素纹晶坯 | AE81: 160010007
A82: 80 | B82: 鲜牛乳 | C82: 生活物品 | D82: 白 | E82: 47 | F82: 1 | G82: 1 | H82: 1 | I82: 1008 | J82: 1008 | K82: 1008 | L82: 605 | M82: 1.00786 | N82: 151 | O82: 15120 | P82: 9.075 | Q82: 50 | R82: 生鲜牛乳，营养温润，可直接饮用。 | S82: 160060007 | AD82: 残痕矿坯 | AE82: 160010008
A83: 81 | B83: 破旧衣物 | C83: 生活物品 | D83: 白 | E83: 48 | F83: 3 | G83: 3 | H83: 0.8 | I83: 7193 | J83: 999 | K83: 799 | L83: 4316 | M83: 0.99879 | N83: 1079 | O83: 107895 | P83: 64.74 | Q83: 358 | R83: 布料多处磨损撕裂，沾染尘污与霉斑，纤维松散破旧，带着尘封已久的暗沉气息。 | S83: 160060002 | AD83: 淬火熟铁矿 | AE83: 160010009
... A465: 463 | B465: 白双刀 | C465: 武器 | D465: 白 | E465: 42 | F465: 4 | G465: 2 | H465: 0.84 | I465: 6693 | J465: 996 | K465: 837 | L465: 4016 | M465: 0.9955 | N465: 1004 | O465: 100395 | P465: 60.24 | Q465: 334 | R465: 以攻速为核心的双持近战武器，攻速极快，连招灵活，擅长持续输出与灵活突进。 | S465: 230040000 | AD465: 引香研磨器 | AE465: 160060046
A466: 464 | B466: 高级护盾药剂 | C466: 药品 | D466: 金 | E466: 1 | F466: 1 | G466: 2 | H466: 0.97 | I466: 194582 | J466: 100300 | K466: 97291 | L466: 116749 | M466: 1.003 | N466: 29187 | O466: 2918730 | P466: 1751.235 | Q466: 9696 | R466: 虹蓝色的顶级药剂，形成的防护屏障近乎不灭，持续时间超长。 | S466: #N/A | AD466: 月转仙酿 | AE466: 160060047
A467: 465 | B467: 高级移速药剂 | C467: 药品 | D467: 金 | E467: 2 | F467: 1 | G467: 2 | H467: 0.97 | I467: 192487 | J467: 99220 | K467: 96243 | L467: 115492 | M467: 0.9922 | N467: 28873 | O467: 2887305 | P467: 1732.38 | Q467: 9591 | R467: 虹绿色的顶级药剂，赋予风之神速，身体灵动性达到极致。 | S467: #N/A | AD467: 定温玉壶 | AE467: 160060048
...

Sheet Sheet3
