Workbook

Sheet Sheet1
A1: 序号 | B1: 物品名称 | C1: 物品分类 | D1: 品质 | E1: 组内序号 | F1: 长 | G1: 宽 | H1: 面积价值衰减 | I1: 初始定价 | J1: 单格价值 | K1: 衰减后单格价值 | L1: 系统回收价(不变) | M1: 价值浮动系数 | N1: 售价下限 | O1: 售价上限 | P1: 最低保证金 | Q1: 价格区间长度 | R1: 道具描述 | S1: 物品id | T1: 面积 | U1: 衰减系数 | AD1: name | AE1: id
L2: 0.6 | M2: ±1.00% | N2: 0.15 | O2: 15 | P2: 0.009 | Q2: 0.0033554795
A3: 1 | B3: 远古龙心 | C3: 生物材料 | D3: 红 | E3: 1 | F3: 3 | G3: 3 | H3: =VLOOKUP(F3*G3,$T$3:$U$11,2,FALSE) -> 0.8 | I3: =ROUND(F3*G3*J3*H3,0) -> 2176697 | J3: =ROUND(VLOOKUP(D3,[1]物品容器!$T$3:$U$8,2,FALSE)*M3,0) -> 302319 | K3: =ROUND(J3*H3,0) -> 241855 | L3: =ROUND($I3*L$2,0) -> 1306018 | M3: 1.00773 | N3: =ROUND($I3*N$2,0) -> 326505 | O3: =ROUND($I3*O$2,0) -> 32650455 | P3: =L3*1.5% -> 19590.27 | Q3: =ROUND((O3-N3)*$Q$2,0) -> 108462 | R3: 仍在微弱跳动的龙之心脏，蕴含庞大生命力，蕴含极致的生命与力量本源。 | S3: =VLOOKUP(B3,$AD:$AE,2,FALSE) -> 160020043 | T3: 1 | U3: 1
A4: 2 | B4: 生命之树精华 | C4: 生物材料 | D4: 红 | E4: 2 | F4: 3 | G4: 3 | H4: =VLOOKUP(F4*G4,$T$3:$U$11,2,FALSE) -> 0.8 | I4: =ROUND(F4*G4*J4*H4,0) -> 2143325 | J4: =ROUND(VLOOKUP(D4,[1]物品容器!$T$3:$U$8,2,FALSE)*M4,0) -> 297684 | K4: =ROUND(J4*H4,0) -> 238147 | L4: =ROUND($I4*L$2,0) -> 1285995 | M4: 0.99228 | N4: =ROUND($I4*N$2,0) -> 321499 | O4: =ROUND($I4*O$2,0) -> 32149875 | P4: =L4*1.5% -> 19289.925 | Q4: =ROUND((O4-N4)*$Q$2,0) -> 106799 | R4: 从世界树树芯中提取的翠绿色液体，拥有极强的生机修复之力。 | S4: =VLOOKUP(B4,$AD:$AE,2,FALSE) -> 160020044 | T4: 2 | U4: 0.97
A5: 3 | B5: 龙骨标本 | C5: 生物材料 | D5: 红 | E5: 3 | F5: 2 | G5: 2 | H5: =VLOOKUP(F5*G5,$T$3:$U$11,2,FALSE) -> 0.91 | I5: =ROUND(F5*G5*J5*H5,0) -> 1096095 | J5: =ROUND(VLOOKUP(D5,[1]物品容器!$T$3:$U$8,2,FALSE)*M5,0) -> 301125 | K5: =ROUND(J5*H5,0) -> 274024 | L5: =ROUND($I5*L$2,0) -> 657657 | M5: 1.00375 | N5: =ROUND($I5*N$2,0) -> 164414 | O5: =ROUND($I5*O$2,0) -> 16441425 | P5: =L5*1.5% -> 9864.855 | Q5: =ROUND((O5-N5)*$Q$2,0) -> 54617 | R5: 保存完好的巨龙骨骼碎片，具备极强的结构稳定性与魔力传导性。 | S5: =VLOOKUP(B5,$AD:$AE,2,FALSE) -> 160020045 | T5: 3 | U5: 0.94
A6: 4 | B6: 不朽之骨 | C6: 生物材料 | D6: 红 | E6: 4 | F6: 2 | G6: 3 | H6: =VLOOKUP(F6*G6,$T$3:$U$11,2,FALSE) -> 0.88 | I6: =ROUND(F6*G6*J6*H6,0) -> 1570504 | J6: =ROUND(VLOOKUP(D6,[1]物品容器!$T$3:$U$8,2,FALSE)*M6,0) -> 297444 | K6: =ROUND(J6*H6,0) -> 261751 | L6: =ROUND($I6*L$2,0) -> 942302 | M6: 0.99148 | N6: =ROUND($I6*N$2,0) -> 235576 | O6: =ROUND($I6*O$2,0) -> 23557560 | P6: =L6*1.5% -> 14134.53 | Q6: =ROUND((O6-N6)*$Q$2,0) -> 78256 | R6: 来自不死生物的骨骼，带有抗腐与不灭特性。 | S6: =VLOOKUP(B6,$AD:$AE,2,FALSE) -> 160020046 | T6: 4 | U6: 0.91
A7: 5 | B7: 神圣羽毛 | C7: 生物材料 | D7: 红 | E7: 5 | F7: 2 | G7: 3 | H7: =VLOOKUP(F7*G7,$T$3:$U$11,2,FALSE) -> 0.88 | I7: =ROUND(F7*G7*J7*H7,0) -> 1593346 | J7: =ROUND(VLOOKUP(D7,[1]物品容器!$T$3:$U$8,2,FALSE)*M7,0) -> 301770 | K7: =ROUND(J7*H7,0) -> 265558 | L7: =ROUND($I7*L$2,0) -> 956008 | M7: 1.0059 | N7: =ROUND($I7*N$2,0) -> 239002 | O7: =ROUND($I7*O$2,0) -> 23900190 | P7: =L7*1.5% -> 14340.12 | Q7: =ROUND((O7-N7)*$Q$2,0) -> 79395 | R7: 高阶圣兽羽翼脱落之羽，蕴含净化与治愈力量。 | S7: =VLOOKUP(B7,$AD:$AE,2,FALSE) -> 160020047 | T7: 6 | U7: 0.88 | AD7: name:string | AE7: id:number
A8: 6 | B8: 星界灵翼晶核 | C8: 生物材料 | D8: 红 | E8: 6 | F8: 2 | G8: 2 | H8: =VLOOKUP(F8*G8,$T$3:$U$11,2,FALSE) -> 0.91 | I8: =ROUND(F8*G8*J8*H8,0) -> 1084116 | J8: =ROUND(VLOOKUP(D8,[1]物品容器!$T$3:$U$8,2,FALSE)*M8,0) -> 297834 | K8: =ROUND(J8*H8,0) -> 271029 | L8: =ROUND($I8*L$2,0) -> 650470 | M8: 0.99278 | N8: =ROUND($I8*N$2,0) -> 162617 | O8: =ROUND($I8*O$2,0) -> 16261740 | P8: =L8*1.5% -> 9757.05 | Q8: =ROUND((O8-N8)*$Q$2,0) -> 54020 | R8: 星界灵翼巨兽的核心结晶，封存着纯粹的星界能量，兼具净化与魔力增幅的本源之力。 | S8: =VLOOKUP(B8,$AD:$AE,2,FALSE) -> 160020048 | T8: 8 | U8: 0.84 | AE8: -1
A9: 7 | B9: 金鳞龙血 | C9: 生物材料 | D9: 金 | E9: 7 | F9: 1 | G9: 1 | H9: =VLOOKUP(F9*G9,$T$3:$U$11,2,FALSE) -> 1 | I9: =ROUND(F9*G9*J9*H9,0) -> 100388 | J9: =ROUND(VLOOKUP(D9,[1]物品容器!$T$3:$U$8,2,FALSE)*M9,0) -> 100388 | K9: =ROUND(J9*H9,0) -> 100388 | L9: =ROUND($I9*L$2,0) -> 60233 | M9: 1.00388 | N9: =ROUND($I9*N$2,0) -> 15058 | O9: =ROUND($I9*O$2,0) -> 1505820 | P9: =L9*1.5% -> 903.495 | Q9: =ROUND((O9-N9)*$Q$2,0) -> 5002 | R9: 从成年巨龙体内提取的血液，富含高浓度火属性能量。 | S9: =VLOOKUP(B9,$AD:$AE,2,FALSE) -> 160020037 | T9: 9 | U9: 0.8 | AD9: 钻石 | AE9: 1
A10: 8 | B10: 月光花蜜 | C10: 生物材料 | D10: 金 | E10: 8 | F10: 1 | G10: 1 | H10: =VLOOKUP(F10*G10,$T$3:$U$11,2,FALSE) -> 1 | I10: =ROUND(F10*G10*J10*H10,0) -> 99889 | J10: =ROUND(VLOOKUP(D10,[1]物品容器!$T$3:$U$8,2,FALSE)*M10,0) -> 99889 | K10: =ROUND(J10*H10,0) -> 99889 | L10: =ROUND($I10*L$2,0) -> 59933 | M10: 0.99889 | N10: =ROUND($I10*N$2,0) -> 14983 | O10: =ROUND($I10*O$2,0) -> 1498335 | P10: =L10*1.5% -> 898.995 | Q10: =ROUND((O10-N10)*$Q$2,0) -> 4977 | R10: 仅在满月夜采集的花蜜，具有稳定魔力与安神效果。 | S10: =VLOOKUP(B10,$AD:$AE,2,FALSE) -> 160020036 | T10: 10 | U10: 0.75 | AD10: 经验 | AE10: 2
A11: 9 | B11: 黑檀木 | C11: 生物材料 | D11: 金 | E11: 9 | F11: 1 | G11: 2 | H11: =VLOOKUP(F11*G11,$T$3:$U$11,2,FALSE) -> 0.97 | I11: =ROUND(F11*G11*J11*H11,0) -> 195868 | J11: =ROUND(VLOOKUP(D11,[1]物品容器!$T$3:$U$8,2,FALSE)*M11,0) -> 100963 | K11: =ROUND(J11*H11,0) -> 97934 | L11: =ROUND($I11*L$2,0) -> 117521 | M11: 1.00963 | N11: =ROUND($I11*N$2,0) -> 29380 | O11: =ROUND($I11*O$2,0) -> 2938020 | P11: =L11*1.5% -> 1762.815 | Q11: =ROUND((O11-N11)*$Q$2,0) -> 9760 | R11: 质地坚硬如铁的珍稀木料，纹理深邃，是打造高阶器物的良材。 | S11: =VLOOKUP(B11,$AD:$AE,2,FALSE) -> 160020038 | T11: 12 | U11: 0.7 | AD11: VIP经验 | AE11: 3
A12: 10 | B12: 巨蛛毒腺 | C12: 生物材料 | D12: 金 | E12: 10 | F12: 1 | G12: 1 | H12: =VLOOKUP(F12*G12,$T$3:$U$11,2,FALSE) -> 1 | I12: =ROUND(F12*G12*J12*H12,0) -> 100979 | J12: =ROUND(VLOOKUP(D12,[1]物品容器!$T$3:$U$8,2,FALSE)*M12,0) -> 100979 | K12: =ROUND(J12*H12,0) -> 100979 | L12: =ROUND($I12*L$2,0) -> 60587 | M12: 1.00979 | N12: =ROUND($I12*N$2,0) -> 15147 | O12: =ROUND($I12*O$2,0) -> 1514685 | P12: =L12*1.5% -> 908.805 | Q12: =ROUND((O12-N12)*$Q$2,0) -> 5032 | R12: 大型毒蛛体内的毒素腺体，可用于剧毒或腐蚀配方。 | S12: =VLOOKUP(B12,$AD:$AE,2,FALSE) -> 160020039 | AD12: 钻石(弃用) | AE12: 10
A13: 11 | B13: 森林古鹿之角 | C13: 生物材料 | D13: 金 | E13: 11 | F13: 1 | G13: 2 | H13: =VLOOKUP(F13*G13,$T$3:$U$11,2,FALSE) -> 0.97 | I13: =ROUND(F13*G13*J13*H13,0) -> 193503 | J13: =ROUND(VLOOKUP(D13,[1]物品容器!$T$3:$U$8,2,FALSE)*M13,0) -> 99744 | K13: =ROUND(J13*H13,0) -> 96752 | L13: =ROUND($I13*L$2,0) -> 116102 | M13: 0.99744 | N13: =ROUND($I13*N$2,0) -> 29025 | O13: =ROUND($I13*O$2,0) -> 2902545 | P13: =L13*1.5% -> 1741.53 | Q13: =ROUND((O13-N13)*$Q$2,0) -> 9642 | R13: 古老灵鹿的分叉鹿角，具有自然恢复与祝福效果。 | S13: =VLOOKUP(B13,$AD:$AE,2,FALSE) -> 160020040 | AD13: 金币 | AE13: 11
A14: 12 | B14: 渊甲龙鳞 | C14: 生物材料 | D14: 金 | E14: 12 | F14: 2 | G14: 3 | H14: =VLOOKUP(F14*G14,$T$3:$U$11,2,FALSE) -> 0.88 | I14: =ROUND(F14*G14*J14*H14,0) -> 529172 | J14: =ROUND(VLOOKUP(D14,[1]物品容器!$T$3:$U$8,2,FALSE)*M14,0) -> 100222 | K14: =ROUND(J14*H14,0) -> 88195 | L14: =ROUND($I14*L$2,0) -> 317503 | M14: 1.00222 | N14: =ROUND($I14*N$2,0) -> 79376 | O14: =ROUND($I14*O$2,0) -> 7937580 | P14: =L14*1.5% -> 4762.545 | Q14: =ROUND((O14-N14)*$Q$2,0) -> 26368 | R14: 深渊古龙的鳞甲碎片，质地坚不可摧，自带稳固的守护气息。 | S14: =VLOOKUP(B14,$AD:$AE,2,FALSE) -> 160020041 | AD14: 改名卡 | AE14: 201
A15: 13 | B15: 炎羽龙皮 | C15: 生物材料 | D15: 金 | E15: 13 | F15: 1 | G15: 2 | H15: =VLOOKUP(F15*G15,$T$3:$U$11,2,FALSE) -> 0.97 | I15: =ROUND(F15*G15*J15*H15,0) -> 192590 | J15: =ROUND(VLOOKUP(D15,[1]物品容器!$T$3:$U$8,2,FALSE)*M15,0) -> 99273 | K15: =ROUND(J15*H15,0) -> 96295 | L15: =ROUND($I15*L$2,0) -> 115554 | M15: 0.99273 | N15: =ROUND($I15*N$2,0) -> 28889 | O15: =ROUND($I15*O$2,0) -> 2888850 | P15: =L15*1.5% -> 1733.31 | Q15: =ROUND((O15-N15)*$Q$2,0) -> 9597 | R15: 炎翼巨龙的翎羽下皮层，坚韧耐热，蕴含着微弱的炎属性本源。 | S15: =VLOOKUP(B15,$AD:$AE,2,FALSE) -> 160020042 | AD15: 新手战备令 | AE15: 1001
A16: 14 | B16: 细密蛛丝 | C16: 生物材料 | D16: 紫 | E16: 14 | F16: 2 | G16: 2 | H16: =VLOOKUP(F16*G16,$T$3:$U$11,2,FALSE) -> 0.91 | I16: =ROUND(F16*G16*J16*H16,0) -> 109611 | J16: =ROUND(VLOOKUP(D16,[1]物品容器!$T$3:$U$8,2,FALSE)*M16,0) -> 30113 | K16: =ROUND(J16*H16,0) -> 27403 | L16: =ROUND($I16*L$2,0) -> 65767 | M16: 1.00377 | N16: =ROUND($I16*N$2,0) -> 16442 | O16: =ROUND($I16*O$2,0) -> 1644165 | P16: =L16*1.5% -> 986.505 | Q16: =ROUND((O16-N16)*$Q$2,0) -> 5462 | R16: 灵蛛吐出的丝线，纤细却强韧，是制作轻韧装备的优质材料。 | S16: =VLOOKUP(B16,$AD:$AE,2,FALSE) -> 160020032 | AD16: 标准战备令 | AE16: 1002
A17: 15 | B17: 幻角兽血 | C17: 生物材料 | D17: 紫 | E17: 15 | F17: 1 | G17: 1 | H17: =VLOOKUP(F17*G17,$T$3:$U$11,2,FALSE) -> 1 | I17: =ROUND(F17*G17*J17*H17,0) -> 29773 | J17: =ROUND(VLOOKUP(D17,[1]物品容器!$T$3:$U$8,2,FALSE)*M17,0) -> 29773 | K17: =ROUND(J17*H17,0) -> 29773 | L17: =ROUND($I17*L$2,0) -> 17864 | M17: 0.99244 | N17: =ROUND($I17*N$2,0) -> 4466 | O17: =ROUND($I17*O$2,0) -> 446595 | P17: =L17*1.5% -> 267.96 | Q17: =ROUND((O17-N17)*$Q$2,0) -> 1484 | R17: 幻角异兽体内的精纯血液，生机旺盛，流转着鲜活的生命能量。 | S17: =VLOOKUP(B17,$AD:$AE,2,FALSE) -> 160020033 | AD17: 精英战备令 | AE17: 1003
A18: 16 | B18: 岩犀厚甲片 | C18: 生物材料 | D18: 紫 | E18: 16 | F18: 2 | G18: 2 | H18: =VLOOKUP(F18*G18,$T$3:$U$11,2,FALSE) -> 0.91 | I18: =ROUND(F18*G18*J18*H18,0) -> 109284 | J18: =ROUND(VLOOKUP(D18,[1]物品容器!$T$3:$U$8,2,FALSE)*M18,0) -> 30023 | K18: =ROUND(J18*H18,0) -> 27321 | L18: =ROUND($I18*L$2,0) -> 65570 | M18: 1.00075 | N18: =ROUND($I18*N$2,0) -> 16393 | O18: =ROUND($I18*O$2,0) -> 1639260 | P18: =L18*1.5% -> 983.55 | Q18: =ROUND((O18-N18)*$Q$2,0) -> 5445 | R18: 岩犀体表的厚重甲片，质地坚硬，防御性能出众。 | S18: =VLOOKUP(B18,$AD:$AE,2,FALSE) -> 160020034 | AD18: 卫队长 | AE18: 100100
A19: 17 | B19: 紫杉木 | C19: 生物材料 | D19: 紫 | E19: 17 | F19: 1 | G19: 2 | H19: =VLOOKUP(F19*G19,$T$3:$U$11,2,FALSE) -> 0.97 | I19: =ROUND(F19*G19*J19*H19,0) -> 58524 | J19: =ROUND(VLOOKUP(D19,[1]物品容器!$T$3:$U$8,2,FALSE)*M19,0) -> 30167 | K19: =ROUND(J19*H19,0) -> 29262 | L19: =ROUND($I19*L$2,0) -> 35114 | M19: 1.00557 | N19: =ROUND($I19*N$2,0) -> 8779 | O19: =ROUND($I19*O$2,0) -> 877860 | P19: =L19*1.5% -> 526.71 | Q19: =ROUND((O19-N19)*$Q$2,0) -> 2916 | R19: 质地坚韧的珍稀木料，弹性极佳，是打造兵器的上佳材料。 | S19: =VLOOKUP(B19,$AD:$AE,2,FALSE) -> 160020035 | AD19: 暗夜女王 | AE19: 100200
A20: 18 | B20: 韧化藤蔓丝 | C20: 生物材料 | D20: 蓝 | E20: 18 | F20: 1 | G20: 1 | H20: =VLOOKUP(F20*G20,$T$3:$U$11,2,FALSE) -> 1 | I20: =ROUND(F20*G20*J20*H20,0) -> 9909 | J20: =ROUND(VLOOKUP(D20,[1]物品容器!$T$3:$U$8,2,FALSE)*M20,0) -> 9909 | K20: =ROUND(J20*H20,0) -> 9909 | L20: =ROUND($I20*L$2,0) -> 5945 | M20: 0.9909 | N20: =ROUND($I20*N$2,0) -> 1486 | O20: =ROUND($I20*O$2,0) -> 148635 | P20: =L20*1.5% -> 89.175 | Q20: =ROUND((O20-N20)*$Q$2,0) -> 494 | R20: 经自然之力淬炼的藤蔓纤维，柔韧度远超普通植物纤维。 | S20: =VLOOKUP(B20,$AD:$AE,2,FALSE) -> 160020022 | AD20: 海潮祭司 | AE20: 100300
A21: 19 | B21: 穿山甲鳞甲 | C21: 生物材料 | D21: 蓝 | E21: 19 | F21: 2 | G21: 3 | H21: =VLOOKUP(F21*G21,$T$3:$U$11,2,FALSE) -> 0.88 | I21: =ROUND(F21*G21*J21*H21,0) -> 53022 | J21: =ROUND(VLOOKUP(D21,[1]物品容器!$T$3:$U$8,2,FALSE)*M21,0) -> 10042 | K21: =ROUND(J21*H21,0) -> 8837 | L21: =ROUND($I21*L$2,0) -> 31813 | M21: 1.00423 | N21: =ROUND($I21*N$2,0) -> 7953 | O21: =ROUND($I21*O$2,0) -> 795330 | P21: =L21*1.5% -> 477.195 | Q21: =ROUND((O21-N21)*$Q$2,0) -> 2642 | R21: 穿山甲的坚硬鳞片，轻薄坚韧，适合制作轻型防护装备。 | S21: =VLOOKUP(B21,$AD:$AE,2,FALSE) -> 160020023 | AD21: 蝶女 | AE21: 100400
A22: 20 | B22: 硬质橡木 | C22: 生物材料 | D22: 蓝 | E22: 20 | F22: 1 | G22: 2 | H22: =VLOOKUP(F22*G22,$T$3:$U$11,2,FALSE) -> 0.97 | I22: =ROUND(F22*G22*J22*H22,0) -> 19289 | J22: =ROUND(VLOOKUP(D22,[1]物品容器!$T$3:$U$8,2,FALSE)*M22,0) -> 9943 | K22: =ROUND(J22*H22,0) -> 9645 | L22: =ROUND($I22*L$2,0) -> 11573 | M22: 0.99429 | N22: =ROUND($I22*N$2,0) -> 2893 | O22: =ROUND($I22*O$2,0) -> 289335 | P22: =L22*1.5% -> 173.595 | Q22: =ROUND((O22-N22)*$Q$2,0) -> 961 | R22: 质地密实的普通优质木料，是新手阶段打造装备的常用主材。 | S22: =VLOOKUP(B22,$AD:$AE,2,FALSE) -> 160020024 | AD22: 虫母 | AE22: 100500
A23: 21 | B23: 林地浆果 | C23: 生物材料 | D23: 蓝 | E23: 21 | F23: 1 | G23: 1 | H23: =VLOOKUP(F23*G23,$T$3:$U$11,2,FALSE) -> 1 | I23: =ROUND(F23*G23*J23*H23,0) -> 9931 | J23: =ROUND(VLOOKUP(D23,[1]物品容器!$T$3:$U$8,2,FALSE)*M23,0) -> 9931 | K23: =ROUND(J23*H23,0) -> 9931 | L23: =ROUND($I23*L$2,0) -> 5959 | M23: 0.9931 | N23: =ROUND($I23*N$2,0) -> 1490 | O23: =ROUND($I23*O$2,0) -> 148965 | P23: =L23*1.5% -> 89.385 | Q23: =ROUND((O23-N23)*$Q$2,0) -> 495 | R23: 林间常见的野生浆果，可作为基础炼药的初级材料。 | S23: =VLOOKUP(B23,$AD:$AE,2,FALSE) -> 160020025 | AD23: 海潮祭司 | AE23: 100600
... A70: 68 | B70: 麻衣围裙 | C70: 生活物品 | D70: 绿 | E70: 35 | F70: 2 | G70: 2 | H70: =VLOOKUP(F70*G70,$T$3:$U$11,2,FALSE) -> 0.91 | I70: =ROUND(F70*G70*J70*H70,0) -> 11029 | J70: =ROUND(VLOOKUP(D70,[1]物品容器!$T$3:$U$8,2,FALSE)*M70,0) -> 3030 | K70: =ROUND(J70*H70,0) -> 2757 | L70: =ROUND($I70*L$2,0) -> 6617 | M70: 1.00985 | N70: =ROUND($I70*N$2,0) -> 1654 | O70: =ROUND($I70*O$2,0) -> 165435 | P70: =L70*1.5% -> 99.255 | Q70: =ROUND((O70-N70)*$Q$2,0) -> 550 | R70: 烹饪时穿戴，防止衣物沾染油污。 | S70: =VLOOKUP(B70,$AD:$AE,2,FALSE) -> 160060015 | AD70: 大回复药 | AE70: 150000003
A71: 69 | B71: 编织草垫 | C71: 生活物品 | D71: 绿 | E71: 36 | F71: 2 | G71: 2 | H71: =VLOOKUP(F71*G71,$T$3:$U$11,2,FALSE) -> 0.91 | I71: =ROUND(F71*G71*J71*H71,0) -> 10953 | J71: =ROUND(VLOOKUP(D71,[1]物品容器!$T$3:$U$8,2,FALSE)*M71,0) -> 3009 | K71: =ROUND(J71*H71,0) -> 2738 | L71: =ROUND($I71*L$2,0) -> 6572 | M71: 1.003 | N71: =ROUND($I71*N$2,0) -> 1643 | O71: =ROUND($I71*O$2,0) -> 164295 | P71: =L71*1.5% -> 98.58 | Q71: =ROUND((O71-N71)*$Q$2,0) -> 546 | R71: 干草编织而成，可铺垫坐卧，简易实用。 | S71: =VLOOKUP(B71,$AD:$AE,2,FALSE) -> 160060016 | AD71: 小通用武器维修 | AE71: 151000001 | AF71: =_xlfn.TEXTJOIN(",",TRUE,AE71:AE76) -> 151000001,151000002,151000003,152000001,152000002,152000003
A72: 70 | B72: 食盐 | C72: 生活物品 | D72: 绿 | E72: 37 | F72: 1 | G72: 1 | H72: =VLOOKUP(F72*G72,$T$3:$U$11,2,FALSE) -> 1 | I72: =ROUND(F72*G72*J72*H72,0) -> 2977 | J72: =ROUND(VLOOKUP(D72,[1]物品容器!$T$3:$U$8,2,FALSE)*M72,0) -> 2977 | K72: =ROUND(J72*H72,0) -> 2977 | L72: =ROUND($I72*L$2,0) -> 1786 | M72: 0.99218 | N72: =ROUND($I72*N$2,0) -> 447 | O72: =ROUND($I72*O$2,0) -> 44655 | P72: =L72*1.5% -> 26.79 | Q72: =ROUND((O72-N72)*$Q$2,0) -> 148 | R72: 基础调味品，提味增鲜，烹饪必备。 | S72: =VLOOKUP(B72,$AD:$AE,2,FALSE) -> 160060017 | AD72: 中通用武器维修 | AE72: 151000002
A73: 71 | B73: 麦香面包 | C73: 生活物品 | D73: 绿 | E73: 38 | F73: 1 | G73: 1 | H73: =VLOOKUP(F73*G73,$T$3:$U$11,2,FALSE) -> 1 | I73: =ROUND(F73*G73*J73*H73,0) -> 3004 | J73: =ROUND(VLOOKUP(D73,[1]物品容器!$T$3:$U$8,2,FALSE)*M73,0) -> 3004 | K73: =ROUND(J73*H73,0) -> 3004 | L73: =ROUND($I73*L$2,0) -> 1802 | M73: 1.00125 | N73: =ROUND($I73*N$2,0) -> 451 | O73: =ROUND($I73*O$2,0) -> 45060 | P73: =L73*1.5% -> 27.03 | Q73: =ROUND((O73-N73)*$Q$2,0) -> 150 | R73: 基础主食，松软饱腹，日常食用。 | S73: =VLOOKUP(B73,$AD:$AE,2,FALSE) -> 160060018 | AD73: 大通用武器维修 | AE73: 151000003
A74: 72 | B74: 水壶 | C74: 生活物品 | D74: 绿 | E74: 39 | F74: 1 | G74: 1 | H74: =VLOOKUP(F74*G74,$T$3:$U$11,2,FALSE) -> 1 | I74: =ROUND(F74*G74*J74*H74,0) -> 2980 | J74: =ROUND(VLOOKUP(D74,[1]物品容器!$T$3:$U$8,2,FALSE)*M74,0) -> 2980 | K74: =ROUND(J74*H74,0) -> 2980 | L74: =ROUND($I74*L$2,0) -> 1788 | M74: 0.99322 | N74: =ROUND($I74*N$2,0) -> 447 | O74: =ROUND($I74*O$2,0) -> 44700 | P74: =L74*1.5% -> 26.82 | Q74: =ROUND((O74-N74)*$Q$2,0) -> 148 | R74: 普通盛水器具，用于外出携带饮水。 | S74: =VLOOKUP(B74,$AD:$AE,2,FALSE) -> 160060019 | AD74: 小通用防具维修 | AE74: 152000001
A75: 73 | B75: 淡酒 | C75: 生活物品 | D75: 绿 | E75: 40 | F75: 1 | G75: 2 | H75: =VLOOKUP(F75*G75,$T$3:$U$11,2,FALSE) -> 0.97 | I75: =ROUND(F75*G75*J75*H75,0) -> 5773 | J75: =ROUND(VLOOKUP(D75,[1]物品容器!$T$3:$U$8,2,FALSE)*M75,0) -> 2976 | K75: =ROUND(J75*H75,0) -> 2887 | L75: =ROUND($I75*L$2,0) -> 3464 | M75: 0.992 | N75: =ROUND($I75*N$2,0) -> 866 | O75: =ROUND($I75*O$2,0) -> 86595 | P75: =L75*1.5% -> 51.96 | Q75: =ROUND((O75-N75)*$Q$2,0) -> 288 | R75: 度数极低的酒液，口感清淡，不易醉人。 | S75: =VLOOKUP(B75,$AD:$AE,2,FALSE) -> 160060020 | AD75: 中通用防具维修 | AE75: 152000002
A76: 74 | B76: 擦布 | C76: 生活物品 | D76: 绿 | E76: 41 | F76: 1 | G76: 1 | H76: =VLOOKUP(F76*G76,$T$3:$U$11,2,FALSE) -> 1 | I76: =ROUND(F76*G76*J76*H76,0) -> 3009 | J76: =ROUND(VLOOKUP(D76,[1]物品容器!$T$3:$U$8,2,FALSE)*M76,0) -> 3009 | K76: =ROUND(J76*H76,0) -> 3009 | L76: =ROUND($I76*L$2,0) -> 1805 | M76: 1.003 | N76: =ROUND($I76*N$2,0) -> 451 | O76: =ROUND($I76*O$2,0) -> 45135 | P76: =L76*1.5% -> 27.075 | Q76: =ROUND((O76-N76)*$Q$2,0) -> 150 | R76: 棉质布料，用于擦拭桌面、餐具。 | S76: =VLOOKUP(B76,$AD:$AE,2,FALSE) -> 160060021 | AD76: 大通用防具维修 | AE76: 152000003
A77: 75 | B77: 实木餐盘 | C77: 生活物品 | D77: 绿 | E77: 42 | F77: 2 | G77: 2 | H77: =VLOOKUP(F77*G77,$T$3:$U$11,2,FALSE) -> 0.91 | I77: =ROUND(F77*G77*J77*H77,0) -> 11015 | J77: =ROUND(VLOOKUP(D77,[1]物品容器!$T$3:$U$8,2,FALSE)*M77,0) -> 3026 | K77: =ROUND(J77*H77,0) -> 2754 | L77: =ROUND($I77*L$2,0) -> 6609 | M77: 1.00875 | N77: =ROUND($I77*N$2,0) -> 1652 | O77: =ROUND($I77*O$2,0) -> 165225 | P77: =L77*1.5% -> 99.135 | Q77: =ROUND((O77-N77)*$Q$2,0) -> 549 | R77: 实木制成，用于盛放食物、蔬果。 | S77: =VLOOKUP(B77,$AD:$AE,2,FALSE) -> 160060022 | AD77: 地图1测试钥匙 | AE77: 153010001
A78: 76 | B78: 老旧油灯 | C78: 生活物品 | D78: 绿 | E78: 43 | F78: 2 | G78: 2 | H78: =VLOOKUP(F78*G78,$T$3:$U$11,2,FALSE) -> 0.91 | I78: =ROUND(F78*G78*J78*H78,0) -> 10949 | J78: =ROUND(VLOOKUP(D78,[1]物品容器!$T$3:$U$8,2,FALSE)*M78,0) -> 3008 | K78: =ROUND(J78*H78,0) -> 2737 | L78: =ROUND($I78*L$2,0) -> 6569 | M78: 1.00277 | N78: =ROUND($I78*N$2,0) -> 1642 | O78: =ROUND($I78*O$2,0) -> 164235 | P78: =L78*1.5% -> 98.535 | Q78: =ROUND((O78-N78)*$Q$2,0) -> 546 | R78: 使用已久的旧油灯，照明效果一般，仍可使用。 | S78: =VLOOKUP(B78,$AD:$AE,2,FALSE) -> 160060023 | AD78: 地图2测试钥匙 | AE78: 153020001
A79: 77 | B79: 杂粮饼干 | C79: 生活物品 | D79: 绿 | E79: 44 | F79: 1 | G79: 1 | H79: =VLOOKUP(F79*G79,$T$3:$U$11,2,FALSE) -> 1 | I79: =ROUND(F79*G79*J79*H79,0) -> 3002 | J79: =ROUND(VLOOKUP(D79,[1]物品容器!$T$3:$U$8,2,FALSE)*M79,0) -> 3002 | K79: =ROUND(J79*H79,0) -> 3002 | L79: =ROUND($I79*L$2,0) -> 1801 | M79: 1.00076 | N79: =ROUND($I79*N$2,0) -> 450 | O79: =ROUND($I79*O$2,0) -> 45030 | P79: =L79*1.5% -> 27.015 | Q79: =ROUND((O79-N79)*$Q$2,0) -> 150 | R79: 谷物压制的饼食，耐储存，便携充饥。 | S79: =VLOOKUP(B79,$AD:$AE,2,FALSE) -> 160060024 | AD79: 地图3测试钥匙 | AE79: 153030001
A80: 78 | B80: 日晒果干 | C80: 生活物品 | D80: 绿 | E80: 45 | F80: 1 | G80: 1 | H80: =VLOOKUP(F80*G80,$T$3:$U$11,2,FALSE) -> 1 | I80: =ROUND(F80*G80*J80*H80,0) -> 2970 | J80: =ROUND(VLOOKUP(D80,[1]物品容器!$T$3:$U$8,2,FALSE)*M80,0) -> 2970 | K80: =ROUND(J80*H80,0) -> 2970 | L80: =ROUND($I80*L$2,0) -> 1782 | M80: 0.99012 | N80: =ROUND($I80*N$2,0) -> 446 | O80: =ROUND($I80*O$2,0) -> 44550 | P80: =L80*1.5% -> 26.73 | Q80: =ROUND((O80-N80)*$Q$2,0) -> 148 | R80: 鲜果脱水制成，保留甜味，方便存放食用。 | S80: =VLOOKUP(B80,$AD:$AE,2,FALSE) -> 160060025 | AD80: 青铜矿 | AE80: 160010001
A81: 79 | B81: 旧油灯 | C81: 生活物品 | D81: 白 | E81: 46 | F81: 2 | G81: 3 | H81: =VLOOKUP(F81*G81,$T$3:$U$11,2,FALSE) -> 0.88 | I81: =ROUND(F81*G81*J81*H81,0) -> 5232 | J81: =ROUND(VLOOKUP(D81,[1]物品容器!$T$3:$U$8,2,FALSE)*M81,0) -> 991 | K81: =ROUND(J81*H81,0) -> 872 | L81: =ROUND($I81*L$2,0) -> 3139 | M81: 0.99096 | N81: =ROUND($I81*N$2,0) -> 785 | O81: =ROUND($I81*O$2,0) -> 78480 | P81: =L81*1.5% -> 47.085 | Q81: =ROUND((O81-N81)*$Q$2,0) -> 261 | R81: 灯身布满烟熏痕迹与斑驳锈迹，灯芯焦枯蜷曲，散发出陈旧而暗沉的油烟气息。 | S81: =VLOOKUP(B81,$AD:$AE,2,FALSE) -> 160060001 | AD81: 铁矿 | AE81: 160010002
A82: 80 | B82: 鲜牛乳 | C82: 生活物品 | D82: 白 | E82: 47 | F82: 1 | G82: 1 | H82: =VLOOKUP(F82*G82,$T$3:$U$11,2,FALSE) -> 1 | I82: =ROUND(F82*G82*J82*H82,0) -> 1008 | J82: =ROUND(VLOOKUP(D82,[1]物品容器!$T$3:$U$8,2,FALSE)*M82,0) -> 1008 | K82: =ROUND(J82*H82,0) -> 1008 | L82: =ROUND($I82*L$2,0) -> 605 | M82: 1.00786 | N82: =ROUND($I82*N$2,0) -> 151 | O82: =ROUND($I82*O$2,0) -> 15120 | P82: =L82*1.5% -> 9.075 | Q82: =ROUND((O82-N82)*$Q$2,0) -> 50 | R82: 生鲜牛乳，营养温润，可直接饮用。 | S82: =VLOOKUP(B82,$AD:$AE,2,FALSE) -> 160060007 | AD82: 高原锰石 | AE82: 160010003
A83: 81 | B83: 破旧衣物 | C83: 生活物品 | D83: 白 | E83: 48 | F83: 3 | G83: 3 | H83: =VLOOKUP(F83*G83,$T$3:$U$11,2,FALSE) -> 0.8 | I83: =ROUND(F83*G83*J83*H83,0) -> 7193 | J83: =ROUND(VLOOKUP(D83,[1]物品容器!$T$3:$U$8,2,FALSE)*M83,0) -> 999 | K83: =ROUND(J83*H83,0) -> 799 | L83: =ROUND($I83*L$2,0) -> 4316 | M83: 0.99879 | N83: =ROUND($I83*N$2,0) -> 1079 | O83: =ROUND($I83*O$2,0) -> 107895 | P83: =L83*1.5% -> 64.74 | Q83: =ROUND((O83-N83)*$Q$2,0) -> 358 | R83: 布料多处磨损撕裂，沾染尘污与霉斑，纤维松散破旧，带着尘封已久的暗沉气息。 | S83: =VLOOKUP(B83,$AD:$AE,2,FALSE) -> 160060002 | AD83: 赤纹铜矿 | AE83: 160010004
... A423: 421 | B423: 世界之牌 | C423: 艺术古董 | D423: 白 | E423: 127 | F423: 1 | G423: 1 | H423: =VLOOKUP(F423*G423,$T$3:$U$11,2,FALSE) -> 1 | I423: =ROUND(F423*G423*J423*H423,0) -> 1007 | J423: =ROUND(VLOOKUP(D423,[1]物品容器!$T$3:$U$8,2,FALSE)*M423,0) -> 1007 | K423: =ROUND(J423*H423,0) -> 1007 | L423: =ROUND($I423*L$2,0) -> 604 | M423: 1.00727 | N423: =ROUND($I423*N$2,0) -> 151 | O423: =ROUND($I423*O$2,0) -> 15105 | P423: =L423*1.5% -> 9.06 | Q423: =ROUND((O423-N423)*$Q$2,0) -> 50 | R423: 完整与终结的象征，有人说它意味着“一切已经完成”。 | S423: =VLOOKUP(B423,$AD:$AE,2,FALSE) -> 160050022 | AD423: 帝国荣誉勋章套组 | AE423: 160050127
A424: 422 | B424: 红剑 | C424: 武器 | D424: 红 | E424: 1 | F424: 5 | G424: 2 | H424: =VLOOKUP(F424*G424,$T$3:$U$11,2,FALSE) -> 0.75 | I424: =ROUND(F424*G424*J424*H424,0) -> 1130963 | J424: =ROUND(VLOOKUP(D424,[1]物品容器!$T$3:$U$8,2,FALSE)*M424,0)*0.5 -> 150795 | K424: =ROUND(J424*H424,0) -> 113096 | L424: =ROUND($I424*L$2,0) -> 678578 | M424: 1.0053 | N424: =ROUND($I424*N$2,0) -> 169644 | O424: =ROUND($I424*O$2,0) -> 16964445 | P424: =L424*1.5% -> 10178.67 | Q424: =ROUND((O424-N424)*$Q$2,0) -> 56355 | R424: 以锋刃为核心的近战武器，攻守均衡，适配绝大多数近战职业，是最经典的武器类型。 | S424: =VLOOKUP(B424,$AD:$AE,2,FALSE) -> 230010500 | AD424: 旧油灯 | AE424: 160060001
A425: 423 | B425: 红弓 | C425: 武器 | D425: 红 | E425: 2 | F425: 4 | G425: 2 | H425: =VLOOKUP(F425*G425,$T$3:$U$11,2,FALSE) -> 0.84 | I425: =ROUND(F425*G425*J425*H425,0) -> 1014149 | J425: =ROUND(VLOOKUP(D425,[1]物品容器!$T$3:$U$8,2,FALSE)*M425,0)*0.5 -> 150915 | K425: =ROUND(J425*H425,0) -> 126769 | L425: =ROUND($I425*L$2,0) -> 608489 | M425: 1.0061 | N425: =ROUND($I425*N$2,0) -> 152122 | O425: =ROUND($I425*O$2,0) -> 15212235 | P425: =L425*1.5% -> 9127.335 | Q425: =ROUND((O425-N425)*$Q$2,0) -> 50534 | R425: 以箭矢为媒介的远程武器，射程极远，主打精准打击与持续输出，是远程物理系的核心选择。 | S425: =VLOOKUP(B425,$AD:$AE,2,FALSE) -> 230070500 | AD425: 破旧衣物 | AE425: 160060002
...

Sheet Sheet2

Sheet Sheet3
